Workbook
Name Akun: [1]Akun!$A$1:$G$65536
Name BLN: #REF!
Name BUKU_BESAR_HUTANG_DAGANG: 'Bk Hutang'!$A$5
Name BUKU_BESAR_INVENTARIS: #REF!
Name DAF_AKUN: Akun!$A:$G
Name DAF_KODE: Kode!$A:$F
Name DARKOD_BANTU: Kode!$B$10:$B$188
Name ERR: 'Data GL'!$O$4
Name Excel_BuiltIn__FilterDatabase_4: Jurnal!$F$8:$O$602
Name HPP: #REF!
Name Hugang: Kode!$B$11:$B$89
Name INVENTARIS: Kode!$B$146+Kode!$B$146:$B$170
Name JU_AKUN: Jurnal!$A:$O
Name JU_KODE: Jurnal!$C:$O
Name KENDARAAN: Kode!$B$173:$B$177
Name KKKKKKKKKKKK: [2]Akun!$B$10:$B$66
Name KODE: Kode!$A$10:$A$214
Name Nabantu: Kode!$B$10:$B$215
Name NAMA: #REF!
Name NAMA_BANTU: Kode!$B$10:$B$214
Name NamaAkun: Akun!$B$10:$B$116
Name NL: 'Neraca Lajur'!$A$1:$J$115
Name Nokun: Akun!$A$10:$A$116
Name not: '[1]Data GL'!#REF!
Name Pitgang: Kode!$B$91:$B$130
Name PIUTANG_DAGANG: Kode!$B$90
Name Tarkun: Akun!$A$10:$G$124
Name TGL: #REF!
Name THN: #REF!

Sheet Data GL
C3: GENERAL LEDGER
C4: Jenis Usaha | E4: PERCETAKAN | O4: =TRUE() -> TRUE
C5: Alamat | E5: JL. Prof Dr. Yohannes 1099 YK | O5: 43101
C6: Nama Pengusaha | E6: CV. SPEKTRA DIGITAL ARTWORK | O6: AND(NOW()>O5;NOW()<O6)
C7: Periode Pembukuan | E7: Jan
C8: Tahun Buku | E8: 2026

Sheet Kode
A1: ='[3]Data GL'!E6 -> CV. SPEKTRA DIGITAL ARTWORK
A2: ='[3]Data GL'!E4 -> PERCETAKAN
A3: ='[3]Data GL'!E5 -> JL. Prof Dr. Yohannes 1099 YK
A5: DAFTAR KODE PEMBANTU
A6: =CONCATENATE('[3]Data GL'!E7," -"," TAHUN"," ",'[3]Data GL'!E8) -> Jan - TAHUN 2026
A8: No | B8: Lawan Transaksi | E8: Kode | F8: Saldo Awal
B9: Nama | C9: NPWP | D9: Alamat
A10: A | B10: HUTANG DAGANG
A11: 1 | B11: Aneka Warna Indah, PT | C11: 0013041108073000 | E11: H-001 | F11: 89792000
A12: 2 | B12: Artha Inti Lestari, PT | C12: 0023419682036000 | E12: H-002 | F12: 5172600
A13: 3 | B13: Jaya Sejahtera, CV | C13: 0814248126543000 | E13: H-003 | F13: 3685010
A14: 4 | B14: Kurnia Jaya, CV | C14: 0026564468504000 | E14: H-004 | F14: 1295903
A15: 5 | B15: Mulia Mandiri Supply, PT | C15: 0027922004044000 | E15: H-005 | F15: 77920499
A16: 6 | B16: Multi Prima Karya Sejati, CV | C16: 0022311278085000 | E16: H-006 | F16: 2234427
A17: 7 | B17: Multiviscomindo, PT | C17: 0027962547062000 | E17: H-007 | F17: 231328247
A18: 8 | B18: Nusign Supply Indonesia, PT | C18: 0311882641418000 | E18: H-008 | F18: 522471950
A19: 9 | B19: Putra Mutiara Jaya, PT | C19: 0029132289424000 | E19: H-009 | F19: 32490018
A20: 10 | B20: Samafitro, PT | C20: 0013109087073000 | E20: H-010 | F20: 89698276
A21: 11 | B21: Tri Mitra Sejati, CV | C21: 0755762911503000 | E21: H-011 | F21: 1680025
A22: 12 | B22: Omega Garda Rupla, PT | C22: 0026450528543000 | E22: H-012
A23: 13 | B23: Mitra Abadi Jaya Mandiri, CV | C23: 0314894494541000 | E23: H-013
A24: 14 | B24: Attaya Global Visindo, PT | C24: 0835815531009000 | E24: H-014
A25: 15
A26: 16
A27: 17
A28: 18
A29: 19
A30: 20
A31: 21
A32: 22
A33: 23
A34: 24
A35: 25
A36: Jumlah | F36: =SUM(F11:F35) -> 1.057769e+09 | H36: 7.3942024e+09 | I36: selisih dgn yg dilapor SPT | J36: =H36-F36 -> 6336433416
A37: B | B37: PIUTANG DAGANG
A38: 1 | B38: Artindo Grafika Printing, PT | C38: 0025062092004000 | E38: P-001 | F38: 1231037841
A39: 2 | B39: CIPUTRA NUSA LESTARI | C39: 0736718511542000 | E39: P-002 | F39: 488400
A40: 3 | B40: CITRA JOGJA KREASI | C40: 0032926479542000 | E40: P-003 | F40: 7229541
A41: 4 | B41: DJARUM, PT | C41: 0012023974511000 | E41: P-004 | F41: 27152215
A42: 5 | B42: K-24 INDONESIA | C42: 0023694474541000 | E42: P-005 | F42: 12654
...

Sheet Akun
A1: ='[3]Data GL'!E6 -> CV. SPEKTRA DIGITAL ARTWORK
A2: ='[3]Data GL'!E4 -> PERCETAKAN
A3: ='[3]Data GL'!E5 -> JL. Prof Dr. Yohannes 1099 YK
A5: DAFTAR AKUN
A6: =CONCATENATE('[3]Data GL'!E7," -"," TAHUN"," ",'[3]Data GL'!E8) -> Jan - TAHUN 2026
A8: Kode | B8: Nama Akun | C8: Pos | D8: Pos | F8: Saldo Awal | G8: Saldo Awal
A9: Akun | C9: Saldo | D9: Laporan | F9: Debet | G9: Kredit
A10: 10000 | B10: AKTIVA
A11: 11000 | B11: AKTIVA LANCAR
A12: 11100 | B12: Kas | C12: D | D12: NR | F12: 650389307
A13: 11101 | B13: Bank | C13: D | D13: NR
A14: 11102 | B14: Piutang Dagang | C14: D | D14: NR | F14: 1281740038
A15: 11103 | B15: Piutang Karyawan | C15: D | D15: NR
A16: 11200 | B16: Persediaan Barang Jadi | C16: D | D16: NR | F16: 1553000000
A17: 11300 | B17: Persediaan Barang Proses | C17: D | D17: NR
A18: 11301 | B18: Persediaan Bahan Baku | C18: D | D18: NR | F18: 10187858027
A19: 11400 | B19: Persediaan Bahan Penolong | C19: D | D19: NR
A20: 11401 | B20: Persediaan Lain-lain | C20: D | D20: NR
A21: 11402 | B21: Ppn Dibayar dimuka | C21: D | D21: NR
A22: 11403 | B22: Pph Pasal 23 | C22: D | D22: NR
A23: 11500 | B23: Pph Pasal 25 | C23: D | D23: NR
A24: 11600 | B24: PPN Masukan | C24: D | D24: NR
A25: 11700 | B25: Uang Muka Pembelian | C25: D | D25: NR
A26: 11800 | B26: Uang Muka Sewa | C26: D | D26: NR
A27: 12000 | B27: AKTIVA TETAP
A28: 12100 | B28: Gedung dan Listrik | C28: D | D28: NR | F28: =166591000-118001958 -> 48589042
A29: 12200 | B29: Peralatan Pabrik | C29: D | D29: NR | F29: =10909833758-4657711650 -> 6252122108
A30: 12300 | B30: Peralatan Kantor | C30: D | D30: NR | F30: =910637468-701727855 -> 208909613
A31: 12400 | B31: Kendaraan | C31: D | D31: NR
A32: 12500 | B32: Investaris Kantor | C32: D | D32: NR
A33: 12601 | B33: Akm. Penyusutan Bangunan | C33: D | D33: NR
A34: 12602 | B34: Akm. Penyusutan Mesin | C34: D | D34: NR
A35: 12603 | B35: Akm. Penyusutan Peralatan Kantor | C35: D | D35: NR
A36: 12604 | B36: Akm. Penyusutan Kendaraan | C36: D | D36: NR
A37: 12605 | B37: Akm. | C37: D | D37: NR
A38: 20000 | B38: KEWAJIBAN
A39: 21100 | B39: Hutang Dagang | C39: K | D39: NR | G39: 7162874124
A40: 22101 | B40: Hutang Pph Final PP 46 | C40: K | D40: NR | G40: 31589467
A41: 22102 | B41: Hutang Pph Pasal 23 | C41: K | D41: NR
A42: 22103 | B42: Hutang Pph Pasal 4(2) | C42: K | D42: NR
...

Sheet Ledger
A1: ='Data GL'!E6 -> CV. SPEKTRA DIGITAL ARTWORK
A2: ='Data GL'!E4 -> PERCETAKAN
A3: ='Data GL'!E5 -> JL. Prof Dr. Yohannes 1099 YK
A5: BUKU BESAR
A6: =CONCATENATE('Data GL'!E7," -"," TAHUN"," ",'Data GL'!E8) -> Jan - TAHUN 2026
B8: =UPPER(IF(H9=0,"",VLOOKUP(H9,Tarkun,2,0))) -> PERSEDIAAN BAHAN PENOLONG
G9: 11801 | H9: 11400
A12: No | B12: Tanggal | C12: =VLOOKUP(H9,DAF_AKUN,3,FALSE) -> D | D12: Bukti | E12: Keterangan | F12: Debet | G12: Kredit | H12: Saldo
E13: Saldo Awal | F13: =IF($C$12="D",VLOOKUP(H9,DAF_AKUN,6,FALSE)+VLOOKUP(H9,DAF_AKUN,7,FALSE),0) -> 0 | G13: =IF($C$12="D",0,VLOOKUP(H9,DAF_AKUN,6,FALSE)+VLOOKUP(H9,DAF_AKUN,7,FALSE)) -> 0 | H13: =SUM(F13:G13) -> 0
A14: =A13+1 -> 1 | B14: =IF(ISERROR(VLOOKUP(A14&H$9,JU_AKUN,6,FALSE)=TRUE),"",VLOOKUP(A14&H$9,JU_AKUN,6,FALSE)) | C14: =IF(ISERROR(VLOOKUP(A14&H$9,JU_AKUN,7,FALSE)=TRUE),"",VLOOKUP(A14&H$9,JU_AKUN,7,FALSE)) | D14: =IF(ISERROR(VLOOKUP(A14&H$9,JU_AKUN,8,FALSE)=TRUE),"",VLOOKUP(A14&H$9,JU_AKUN,8,FALSE)) | E14: =IF(ISERROR(VLOOKUP(A14&H$9,JU_AKUN,9,FALSE)=TRUE),"",VLOOKUP(A14&H$9,JU_AKUN,9,FALSE)) | F14: =IF(ISERROR(VLOOKUP(A14&H$9,JU_AKUN,14,FALSE)=TRUE),"",VLOOKUP(A14&H$9,JU_AKUN,14,FALSE)) | G14: =IF(ISERROR(VLOOKUP(A14&H$9,JU_AKUN,15,FALSE)=TRUE),"",VLOOKUP(A14&H$9,JU_AKUN,15,FALSE)) | H14: =IF(OR(ERR=FALSE,AND(F14="",G14="")),0,IF($C$12="D",$H$13+SUM($F$14:F14)-SUM($G$14:G14),$H$13-SUM($F$14:F14)+SUM($G$14:G14))) -> 0
A15: =A14+1 -> 2 | B15: =IF(ISERROR(VLOOKUP(A15&H$9,JU_AKUN,6,FALSE)=TRUE),"",VLOOKUP(A15&H$9,JU_AKUN,6,FALSE)) | C15: =IF(ISERROR(VLOOKUP(A15&H$9,JU_AKUN,7,FALSE)=TRUE),"",VLOOKUP(A15&H$9,JU_AKUN,7,FALSE)) | D15: =IF(ISERROR(VLOOKUP(A15&H$9,JU_AKUN,8,FALSE)=TRUE),"",VLOOKUP(A15&H$9,JU_AKUN,8,FALSE)) | E15: =IF(ISERROR(VLOOKUP(A15&H$9,JU_AKUN,9,FALSE)=TRUE),"",VLOOKUP(A15&H$9,JU_AKUN,9,FALSE)) | F15: =IF(ISERROR(VLOOKUP(A15&H$9,JU_AKUN,14,FALSE)=TRUE),"",VLOOKUP(A15&H$9,JU_AKUN,14,FALSE)) | G15: =IF(ISERROR(VLOOKUP(A15&H$9,JU_AKUN,15,FALSE)=TRUE),"",VLOOKUP(A15&H$9,JU_AKUN,15,FALSE)) | H15: =IF(OR(ERR=FALSE,AND(F15="",G15="")),0,IF($C$12="D",$H$13+SUM($F$14:F15)-SUM($G$14:G15),$H$13-SUM($F$14:F15)+SUM($G$14:G15))) -> 0
A16: =A15+1 -> 3 | B16: =IF(ISERROR(VLOOKUP(A16&H$9,JU_AKUN,6,FALSE)=TRUE),"",VLOOKUP(A16&H$9,JU_AKUN,6,FALSE)) | C16: =IF(ISERROR(VLOOKUP(A16&H$9,JU_AKUN,7,FALSE)=TRUE),"",VLOOKUP(A16&H$9,JU_AKUN,7,FALSE)) | D16: =IF(ISERROR(VLOOKUP(A16&H$9,JU_AKUN,8,FALSE)=TRUE),"",VLOOKUP(A16&H$9,JU_AKUN,8,FALSE)) | E16: =IF(ISERROR(VLOOKUP(A16&H$9,JU_AKUN,9,FALSE)=TRUE),"",VLOOKUP(A16&H$9,JU_AKUN,9,FALSE)) | F16: =IF(ISERROR(VLOOKUP(A16&H$9,JU_AKUN,14,FALSE)=TRUE),"",VLOOKUP(A16&H$9,JU_AKUN,14,FALSE)) | G16: =IF(ISERROR(VLOOKUP(A16&H$9,JU_AKUN,15,FALSE)=TRUE),"",VLOOKUP(A16&H$9,JU_AKUN,15,FALSE)) | H16: =IF(OR(ERR=FALSE,AND(F16="",G16="")),0,IF($C$12="D",$H$13+SUM($F$14:F16)-SUM($G$14:G16),$H$13-SUM($F$14:F16)+SUM($G$14:G16))) -> 0
A17: =A16+1 -> 4 | B17: =IF(ISERROR(VLOOKUP(A17&H$9,JU_AKUN,6,FALSE)=TRUE),"",VLOOKUP(A17&H$9,JU_AKUN,6,FALSE)) | C17: =IF(ISERROR(VLOOKUP(A17&H$9,JU_AKUN,7,FALSE)=TRUE),"",VLOOKUP(A17&H$9,JU_AKUN,7,FALSE)) | D17: =IF(ISERROR(VLOOKUP(A17&H$9,JU_AKUN,8,FALSE)=TRUE),"",VLOOKUP(A17&H$9,JU_AKUN,8,FALSE)) | E17: =IF(ISERROR(VLOOKUP(A17&H$9,JU_AKUN,9,FALSE)=TRUE),"",VLOOKUP(A17&H$9,JU_AKUN,9,FALSE)) | F17: =IF(ISERROR(VLOOKUP(A17&H$9,JU_AKUN,14,FALSE)=TRUE),"",VLOOKUP(A17&H$9,JU_AKUN,14,FALSE)) | G17: =IF(ISERROR(VLOOKUP(A17&H$9,JU_AKUN,15,FALSE)=TRUE),"",VLOOKUP(A17&H$9,JU_AKUN,15,FALSE)) | H17: =IF(OR(ERR=FALSE,AND(F17="",G17="")),0,IF($C$12="D",$H$13+SUM($F$14:F17)-SUM($G$14:G17),$H$13-SUM($F$14:F17)+SUM($G$14:G17))) -> 0
A18: =A17+1 -> 5 | B18: =IF(ISERROR(VLOOKUP(A18&H$9,JU_AKUN,6,FALSE)=TRUE),"",VLOOKUP(A18&H$9,JU_AKUN,6,FALSE)) | C18: =IF(ISERROR(VLOOKUP(A18&H$9,JU_AKUN,7,FALSE)=TRUE),"",VLOOKUP(A18&H$9,JU_AKUN,7,FALSE)) | D18: =IF(ISERROR(VLOOKUP(A18&H$9,JU_AKUN,8,FALSE)=TRUE),"",VLOOKUP(A18&H$9,JU_AKUN,8,FALSE)) | E18: =IF(ISERROR(VLOOKUP(A18&H$9,JU_AKUN,9,FALSE)=TRUE),"",VLOOKUP(A18&H$9,JU_AKUN,9,FALSE)) | F18: =IF(ISERROR(VLOOKUP(A18&H$9,JU_AKUN,14,FALSE)=TRUE),"",VLOOKUP(A18&H$9,JU_AKUN,14,FALSE)) | G18: =IF(ISERROR(VLOOKUP(A18&H$9,JU_AKUN,15,FALSE)=TRUE),"",VLOOKUP(A18&H$9,JU_AKUN,15,FALSE)) | H18: =IF(OR(ERR=FALSE,AND(F18="",G18="")),0,IF($C$12="D",$H$13+SUM($F$14:F18)-SUM($G$14:G18),$H$13-SUM($F$14:F18)+SUM($G$14:G18))) -> 0
A19: =A18+1 -> 6 | B19: =IF(ISERROR(VLOOKUP(A19&H$9,JU_AKUN,6,FALSE)=TRUE),"",VLOOKUP(A19&H$9,JU_AKUN,6,FALSE)) | C19: =IF(ISERROR(VLOOKUP(A19&H$9,JU_AKUN,7,FALSE)=TRUE),"",VLOOKUP(A19&H$9,JU_AKUN,7,FALSE)) | D19: =IF(ISERROR(VLOOKUP(A19&H$9,JU_AKUN,8,FALSE)=TRUE),"",VLOOKUP(A19&H$9,JU_AKUN,8,FALSE)) | E19: =IF(ISERROR(VLOOKUP(A19&H$9,JU_AKUN,9,FALSE)=TRUE),"",VLOOKUP(A19&H$9,JU_AKUN,9,FALSE)) | F19: =IF(ISERROR(VLOOKUP(A19&H$9,JU_AKUN,14,FALSE)=TRUE),"",VLOOKUP(A19&H$9,JU_AKUN,14,FALSE)) | G19: =IF(ISERROR(VLOOKUP(A19&H$9,JU_AKUN,15,FALSE)=TRUE),"",VLOOKUP(A19&H$9,JU_AKUN,15,FALSE)) | H19: =IF(OR(ERR=FALSE,AND(F19="",G19="")),0,IF($C$12="D",$H$13+SUM($F$14:F19)-SUM($G$14:G19),$H$13-SUM($F$14:F19)+SUM($G$14:G19))) -> 0
A20: =A19+1 -> 7 | B20: =IF(ISERROR(VLOOKUP(A20&H$9,JU_AKUN,6,FALSE)=TRUE),"",VLOOKUP(A20&H$9,JU_AKUN,6,FALSE)) | C20: =IF(ISERROR(VLOOKUP(A20&H$9,JU_AKUN,7,FALSE)=TRUE),"",VLOOKUP(A20&H$9,JU_AKUN,7,FALSE)) | D20: =IF(ISERROR(VLOOKUP(A20&H$9,JU_AKUN,8,FALSE)=TRUE),"",VLOOKUP(A20&H$9,JU_AKUN,8,FALSE)) | E20: =IF(ISERROR(VLOOKUP(A20&H$9,JU_AKUN,9,FALSE)=TRUE),"",VLOOKUP(A20&H$9,JU_AKUN,9,FALSE)) | F20: =IF(ISERROR(VLOOKUP(A20&H$9,JU_AKUN,14,FALSE)=TRUE),"",VLOOKUP(A20&H$9,JU_AKUN,14,FALSE)) | G20: =IF(ISERROR(VLOOKUP(A20&H$9,JU_AKUN,15,FALSE)=TRUE),"",VLOOKUP(A20&H$9,JU_AKUN,15,FALSE)) | H20: =IF(OR(ERR=FALSE,AND(F20="",G20="")),0,IF($C$12="D",$H$13+SUM($F$14:F20)-SUM($G$14:G20),$H$13-SUM($F$14:F20)+SUM($G$14:G20))) -> 0
A21: =A20+1 -> 8 | B21: =IF(ISERROR(VLOOKUP(A21&H$9,JU_AKUN,6,FALSE)=TRUE),"",VLOOKUP(A21&H$9,JU_AKUN,6,FALSE)) | C21: =IF(ISERROR(VLOOKUP(A21&H$9,JU_AKUN,7,FALSE)=TRUE),"",VLOOKUP(A21&H$9,JU_AKUN,7,FALSE)) | D21: =IF(ISERROR(VLOOKUP(A21&H$9,JU_AKUN,8,FALSE)=TRUE),"",VLOOKUP(A21&H$9,JU_AKUN,8,FALSE)) | E21: =IF(ISERROR(VLOOKUP(A21&H$9,JU_AKUN,9,FALSE)=TRUE),"",VLOOKUP(A21&H$9,JU_AKUN,9,FALSE)) | F21: =IF(ISERROR(VLOOKUP(A21&H$9,JU_AKUN,14,FALSE)=TRUE),"",VLOOKUP(A21&H$9,JU_AKUN,14,FALSE)) | G21: =IF(ISERROR(VLOOKUP(A21&H$9,JU_AKUN,15,FALSE)=TRUE),"",VLOOKUP(A21&H$9,JU_AKUN,15,FALSE)) | H21: =IF(OR(ERR=FALSE,AND(F21="",G21="")),0,IF($C$12="D",$H$13+SUM($F$14:F21)-SUM($G$14:G21),$H$13-SUM($F$14:F21)+SUM($G$14:G21))) -> 0
A22: =A21+1 -> 9 | B22: =IF(ISERROR(VLOOKUP(A22&H$9,JU_AKUN,6,FALSE)=TRUE),"",VLOOKUP(A22&H$9,JU_AKUN,6,FALSE)) | C22: =IF(ISERROR(VLOOKUP(A22&H$9,JU_AKUN,7,FALSE)=TRUE),"",VLOOKUP(A22&H$9,JU_AKUN,7,FALSE)) | D22: =IF(ISERROR(VLOOKUP(A22&H$9,JU_AKUN,8,FALSE)=TRUE),"",VLOOKUP(A22&H$9,JU_AKUN,8,FALSE)) | E22: =IF(ISERROR(VLOOKUP(A22&H$9,JU_AKUN,9,FALSE)=TRUE),"",VLOOKUP(A22&H$9,JU_AKUN,9,FALSE)) | F22: =IF(ISERROR(VLOOKUP(A22&H$9,JU_AKUN,14,FALSE)=TRUE),"",VLOOKUP(A22&H$9,JU_AKUN,14,FALSE)) | G22: =IF(ISERROR(VLOOKUP(A22&H$9,JU_AKUN,15,FALSE)=TRUE),"",VLOOKUP(A22&H$9,JU_AKUN,15,FALSE)) | H22: =IF(OR(ERR=FALSE,AND(F22="",G22="")),0,IF($C$12="D",$H$13+SUM($F$14:F22)-SUM($G$14:G22),$H$13-SUM($F$14:F22)+SUM($G$14:G22))) -> 0
A23: =A22+1 -> 10 | B23: =IF(ISERROR(VLOOKUP(A23&H$9,JU_AKUN,6,FALSE)=TRUE),"",VLOOKUP(A23&H$9,JU_AKUN,6,FALSE)) | C23: =IF(ISERROR(VLOOKUP(A23&H$9,JU_AKUN,7,FALSE)=TRUE),"",VLOOKUP(A23&H$9,JU_AKUN,7,FALSE)) | D23: =IF(ISERROR(VLOOKUP(A23&H$9,JU_AKUN,8,FALSE)=TRUE),"",VLOOKUP(A23&H$9,JU_AKUN,8,FALSE)) | E23: =IF(ISERROR(VLOOKUP(A23&H$9,JU_AKUN,9,FALSE)=TRUE),"",VLOOKUP(A23&H$9,JU_AKUN,9,FALSE)) | F23: =IF(ISERROR(VLOOKUP(A23&H$9,JU_AKUN,14,FALSE)=TRUE),"",VLOOKUP(A23&H$9,JU_AKUN,14,FALSE)) | G23: =IF(ISERROR(VLOOKUP(A23&H$9,JU_AKUN,15,FALSE)=TRUE),"",VLOOKUP(A23&H$9,JU_AKUN,15,FALSE)) | H23: =IF(OR(ERR=FALSE,AND(F23="",G23="")),0,IF($C$12="D",$H$13+SUM($F$14:F23)-SUM($G$14:G23),$H$13-SUM($F$14:F23)+SUM($G$14:G23))) -> 0
A24: =A23+1 -> 11 | B24: =IF(ISERROR(VLOOKUP(A24&H$9,JU_AKUN,6,FALSE)=TRUE),"",VLOOKUP(A24&H$9,JU_AKUN,6,FALSE)) | C24: =IF(ISERROR(VLOOKUP(A24&H$9,JU_AKUN,7,FALSE)=TRUE),"",VLOOKUP(A24&H$9,JU_AKUN,7,FALSE)) | D24: =IF(ISERROR(VLOOKUP(A24&H$9,JU_AKUN,8,FALSE)=TRUE),"",VLOOKUP(A24&H$9,JU_AKUN,8,FALSE)) | E24: =IF(ISERROR(VLOOKUP(A24&H$9,JU_AKUN,9,FALSE)=TRUE),"",VLOOKUP(A24&H$9,JU_AKUN,9,FALSE)) | F24: =IF(ISERROR(VLOOKUP(A24&H$9,JU_AKUN,14,FALSE)=TRUE),"",VLOOKUP(A24&H$9,JU_AKUN,14,FALSE)) | G24: =IF(ISERROR(VLOOKUP(A24&H$9,JU_AKUN,15,FALSE)=TRUE),"",VLOOKUP(A24&H$9,JU_AKUN,15,FALSE)) | H24: =IF(OR(ERR=FALSE,AND(F24="",G24="")),0,IF($C$12="D",$H$13+SUM($F$14:F24)-SUM($G$14:G24),$H$13-SUM($F$14:F24)+SUM($G$14:G24))) -> 0
A25: =A24+1 -> 12 | B25: =IF(ISERROR(VLOOKUP(A25&H$9,JU_AKUN,6,FALSE)=TRUE),"",VLOOKUP(A25&H$9,JU_AKUN,6,FALSE)) | C25: =IF(ISERROR(VLOOKUP(A25&H$9,JU_AKUN,7,FALSE)=TRUE),"",VLOOKUP(A25&H$9,JU_AKUN,7,FALSE)) | D25: =IF(ISERROR(VLOOKUP(A25&H$9,JU_AKUN,8,FALSE)=TRUE),"",VLOOKUP(A25&H$9,JU_AKUN,8,FALSE)) | E25: =IF(ISERROR(VLOOKUP(A25&H$9,JU_AKUN,9,FALSE)=TRUE),"",VLOOKUP(A25&H$9,JU_AKUN,9,FALSE)) | F25: =IF(ISERROR(VLOOKUP(A25&H$9,JU_AKUN,14,FALSE)=TRUE),"",VLOOKUP(A25&H$9,JU_AKUN,14,FALSE)) | G25: =IF(ISERROR(VLOOKUP(A25&H$9,JU_AKUN,15,FALSE)=TRUE),"",VLOOKUP(A25&H$9,JU_AKUN,15,FALSE)) | H25: =IF(OR(ERR=FALSE,AND(F25="",G25="")),0,IF($C$12="D",$H$13+SUM($F$14:F25)-SUM($G$14:G25),$H$13-SUM($F$14:F25)+SUM($G$14:G25))) -> 0
... A8459: =A8458+1 -> 8446 | B8459: =IF(ISERROR(VLOOKUP(A8459&H$9,JU_AKUN,6,FALSE)=TRUE),"",VLOOKUP(A8459&H$9,JU_AKUN,6,FALSE)) | C8459: =IF(ISERROR(VLOOKUP(A8459&H$9,JU_AKUN,7,FALSE)=TRUE),"",VLOOKUP(A8459&H$9,JU_AKUN,7,FALSE)) | D8459: =IF(ISERROR(VLOOKUP(A8459&H$9,JU_AKUN,8,FALSE)=TRUE),"",VLOOKUP(A8459&H$9,JU_AKUN,8,FALSE)) | E8459: =IF(ISERROR(VLOOKUP(A8459&H$9,JU_AKUN,9,FALSE)=TRUE),"",VLOOKUP(A8459&H$9,JU_AKUN,9,FALSE)) | F8459: =IF(ISERROR(VLOOKUP(A8459&H$9,JU_AKUN,14,FALSE)=TRUE),"",VLOOKUP(A8459&H$9,JU_AKUN,14,FALSE)) | G8459: =IF(ISERROR(VLOOKUP(A8459&H$9,JU_AKUN,15,FALSE)=TRUE),"",VLOOKUP(A8459&H$9,JU_AKUN,15,FALSE)) | H8459: =IF(OR(ERR=FALSE,AND(F8459="",G8459="")),0,IF($C$12="D",$H$13+SUM($F$14:F8459)-SUM($G$14:G8459),$H$13-SUM($F$14:F8459)+SUM($G$14:G8459))) -> 0
F8460: =SUM(F1:F8258) -> 0 | G8460: =SUM(G1:G8258) -> 11801 | H8460: =+F8460-G8460 -> -11801

Sheet Jurnal
F1: ='Data GL'!E6 -> CV. SPEKTRA DIGITAL ARTWORK
F2: ='Data GL'!E4 -> PERCETAKAN
F3: ='Data GL'!E5 -> JL. Prof Dr. Yohannes 1099 YK
F5: JURNAL UMUM
F6: =CONCATENATE('Data GL'!E7," -"," TAHUN"," ",'Data GL'!E8) -> Jan - TAHUN 2026
A7: -
A8: Akun | B8: Akun | C8: Bantu | D8: Bantu | F8: Tanggal | H8: Bukti | I8: Keterangan | J8: Nama Akun | K8: Kode | L8: Nama Akun Pembantu | M8: Kode | N8: Debet | O8: Kredit | P8: Indikator
A9: 1 | B9: 2 | C9: 1 | D9: 2 | K9: Akun | M9: Bantu
A10: =B10&K10 -> 111100 | B10: =IF(ERR=TRUE,COUNTIF($K$10:K10,K10),0) -> 1 | C10: =D10&M10 -> 1 | D10: =IF(ERR=FALSE,0,COUNTIF($M$10:M10,M10)) -> 1 | F10: 46023 | G10: 2 | I10: Penjualan Retail | J10: =IF(K10=0,"",VLOOKUP(K10,Tarkun,2,0)) -> Kas | K10: 11100 | M10: =IF(L10=0," ",(VLOOKUP(L10,Kode!$B$10:$E$423,4,0))) | N10: 9301100 | P10: =IF(K10="","",IF(AND(K10>0,$M$602=0),"Balance","Unbalance")) -> Balance
A11: =B11&K11 -> 122105 | B11: =IF(ERR=TRUE,COUNTIF($K$10:K11,K11),0) -> 1 | C11: =D11&M11 -> 2 | D11: =IF(ERR=FALSE,0,COUNTIF($M$10:M11,M11)) -> 2 | F11: 46024 | G11: 2 | I11: Penjualan Retail | J11: =IF(K11=0,"",VLOOKUP(K11,Tarkun,2,0)) -> PPN Keluaran | K11: 22105 | M11: =IF(L11=0," ",(VLOOKUP(L11,Kode!$B$10:$E$423,4,0))) | O11: 921730.63 | P11: =IF(K11="","",IF(AND(K11>0,$M$602=0),"Balance","Unbalance")) -> Balance
A12: =B12&K12 -> 141000 | B12: =IF(ERR=TRUE,COUNTIF($K$10:K12,K12),0) -> 1 | C12: =D12&M12 -> 3 | D12: =IF(ERR=FALSE,0,COUNTIF($M$10:M12,M12)) -> 3 | F12: 46025 | G12: 2 | I12: Penjualan Retail | J12: =IF(K12=0,"",VLOOKUP(K12,Tarkun,2,0)) -> Penjualan Barang | K12: 41000 | M12: =IF(L12=0," ",(VLOOKUP(L12,Kode!$B$10:$E$423,4,0))) | O12: 8379369.4 | P12: =IF(K12="","",IF(AND(K12>0,$M$602=0),"Balance","Unbalance")) -> Balance
A13: =B13&K13 -> 0 | B13: =IF(ERR=TRUE,COUNTIF($K$10:K13,K13),0) -> 0 | C13: =D13&M13 -> 4 | D13: =IF(ERR=FALSE,0,COUNTIF($M$10:M13,M13)) -> 4 | F13: 46051 | J13: =IF(K13=0,"",VLOOKUP(K13,Tarkun,2,0)) | M13: =IF(L13=0," ",(VLOOKUP(L13,Kode!$B$10:$E$423,4,0))) | O13: 0 | P13: =IF(K13="","",IF(AND(K13>0,$M$602=0),"Balance","Unbalance"))
A14: =B14&K14 -> 211100 | B14: =IF(ERR=TRUE,COUNTIF($K$10:K14,K14),0) -> 2 | C14: =D14&M14 -> 5 | D14: =IF(ERR=FALSE,0,COUNTIF($M$10:M14,M14)) -> 5 | F14: 46023 | G14: 3 | I14: Penjualan Retail | J14: =IF(K14=0,"",VLOOKUP(K14,Tarkun,2,0)) -> Kas | K14: 11100 | M14: =IF(L14=0," ",(VLOOKUP(L14,Kode!$B$10:$E$423,4,0))) | N14: 19566300 | P14: =IF(K14="","",IF(AND(K14>0,$M$602=0),"Balance","Unbalance")) -> Balance
A15: =B15&K15 -> 222105 | B15: =IF(ERR=TRUE,COUNTIF($K$10:K15,K15),0) -> 2 | C15: =D15&M15 -> 6 | D15: =IF(ERR=FALSE,0,COUNTIF($M$10:M15,M15)) -> 6 | F15: 46026 | G15: 3 | I15: Penjualan Retail | J15: =IF(K15=0,"",VLOOKUP(K15,Tarkun,2,0)) -> PPN Keluaran | K15: 22105 | M15: =IF(L15=0," ",(VLOOKUP(L15,Kode!$B$10:$E$423,4,0))) | O15: 1939002.7 | P15: =IF(K15="","",IF(AND(K15>0,$M$602=0),"Balance","Unbalance")) -> Balance
A16: =B16&K16 -> 241000 | B16: =IF(ERR=TRUE,COUNTIF($K$10:K16,K16),0) -> 2 | C16: =D16&M16 -> 7 | D16: =IF(ERR=FALSE,0,COUNTIF($M$10:M16,M16)) -> 7 | F16: 46027 | G16: 3 | I16: Penjualan Retail | J16: =IF(K16=0,"",VLOOKUP(K16,Tarkun,2,0)) -> Penjualan Barang | K16: 41000 | M16: =IF(L16=0," ",(VLOOKUP(L16,Kode!$B$10:$E$423,4,0))) | O16: 17627297 | P16: =IF(K16="","",IF(AND(K16>0,$M$602=0),"Balance","Unbalance")) -> Balance
A17: =B17&K17 -> 0 | B17: =IF(ERR=TRUE,COUNTIF($K$10:K17,K17),0) -> 0 | C17: =D17&M17 -> 8 | D17: =IF(ERR=FALSE,0,COUNTIF($M$10:M17,M17)) -> 8 | F17: 46051 | J17: =IF(K17=0,"",VLOOKUP(K17,Tarkun,2,0)) | M17: =IF(L17=0," ",(VLOOKUP(L17,Kode!$B$10:$E$423,4,0))) | O17: 0 | P17: =IF(K17="","",IF(AND(K17>0,$M$602=0),"Balance","Unbalance"))
A18: =B18&K18 -> 111700 | B18: =IF(ERR=TRUE,COUNTIF($K$10:K18,K18),0) -> 1 | C18: =D18&M18 -> 9 | D18: =IF(ERR=FALSE,0,COUNTIF($M$10:M18,M18)) -> 9 | F18: 46048 | G18: 5 | I18: DP Mesin Flatbed Allwind Aneka Warna Indah, PT | J18: =IF(K18=0,"",VLOOKUP(K18,Tarkun,2,0)) -> Uang Muka Pembelian | K18: 11700 | M18: =IF(L18=0," ",(VLOOKUP(L18,Kode!$B$10:$E$423,4,0))) | N18: 200000000 | P18: =IF(K18="","",IF(AND(K18>0,$M$602=0),"Balance","Unbalance")) -> Balance
A19: =B19&K19 -> 311100 | B19: =IF(ERR=TRUE,COUNTIF($K$10:K19,K19),0) -> 3 | C19: =D19&M19 -> 10 | D19: =IF(ERR=FALSE,0,COUNTIF($M$10:M19,M19)) -> 10 | F19: 46048 | G19: 5 | I19: DP Mesin Flatbed Allwind Aneka Warna Indah, PT | J19: =IF(K19=0,"",VLOOKUP(K19,Tarkun,2,0)) -> Kas | K19: 11100 | M19: =IF(L19=0," ",(VLOOKUP(L19,Kode!$B$10:$E$423,4,0))) | O19: 200000000 | P19: =IF(K19="","",IF(AND(K19>0,$M$602=0),"Balance","Unbalance")) -> Balance
A20: =B20&K20 -> 411100 | B20: =IF(ERR=TRUE,COUNTIF($K$10:K20,K20),0) -> 4 | C20: =D20&M20 -> 11 | D20: =IF(ERR=FALSE,0,COUNTIF($M$10:M20,M20)) -> 11 | F20: 46023 | G20: 5 | I20: Penjualan Retail | J20: =IF(K20=0,"",VLOOKUP(K20,Tarkun,2,0)) -> Kas | K20: 11100 | M20: =IF(L20=0," ",(VLOOKUP(L20,Kode!$B$10:$E$423,4,0))) | N20: 29812000 | P20: =IF(K20="","",IF(AND(K20>0,$M$602=0),"Balance","Unbalance")) -> Balance
A21: =B21&K21 -> 322105 | B21: =IF(ERR=TRUE,COUNTIF($K$10:K21,K21),0) -> 3 | C21: =D21&M21 -> 12 | D21: =IF(ERR=FALSE,0,COUNTIF($M$10:M21,M21)) -> 12 | F21: 46026 | G21: 5 | I21: Penjualan Retail | J21: =IF(K21=0,"",VLOOKUP(K21,Tarkun,2,0)) -> PPN Keluaran | K21: 22105 | M21: =IF(L21=0," ",(VLOOKUP(L21,Kode!$B$10:$E$423,4,0))) | O21: 2954342.3 | P21: =IF(K21="","",IF(AND(K21>0,$M$602=0),"Balance","Unbalance")) -> Balance
A22: =B22&K22 -> 341000 | B22: =IF(ERR=TRUE,COUNTIF($K$10:K22,K22),0) -> 3 | C22: =D22&M22 -> 13 | D22: =IF(ERR=FALSE,0,COUNTIF($M$10:M22,M22)) -> 13 | F22: 46027 | G22: 5 | I22: Penjualan Retail | J22: =IF(K22=0,"",VLOOKUP(K22,Tarkun,2,0)) -> Penjualan Barang | K22: 41000 | M22: =IF(L22=0," ",(VLOOKUP(L22,Kode!$B$10:$E$423,4,0))) | O22: 26857658 | P22: =IF(K22="","",IF(AND(K22>0,$M$602=0),"Balance","Unbalance")) -> Balance
A23: =B23&K23 -> 112200 | B23: =IF(ERR=TRUE,COUNTIF($K$10:K23,K23),0) -> 1 | C23: =D23&M23 -> 14 | D23: =IF(ERR=FALSE,0,COUNTIF($M$10:M23,M23)) -> 14 | F23: 46051 | G23: 5 | H23: 04002600004962829 | I23: Pembelian Mesin ALLWIN 2512GS UV FLATBED RICOH ke Aneka Warna Indah, PT | J23: =IF(K23=0,"",VLOOKUP(K23,Tarkun,2,0)) -> Peralatan Pabrik | K23: 12200 | M23: =IF(L23=0," ",(VLOOKUP(L23,Kode!$B$10:$E$423,4,0))) | N23: 495495496 | O23: 0 | P23: =IF(K23="","",IF(AND(K23>0,$M$602=0),"Balance","Unbalance")) -> Balance
A24: =B24&K24 -> 111600 | B24: =IF(ERR=TRUE,COUNTIF($K$10:K24,K24),0) -> 1 | C24: =D24&M24 -> 15 | D24: =IF(ERR=FALSE,0,COUNTIF($M$10:M24,M24)) -> 15 | F24: 46051 | G24: 5 | H24: 04002600004962829 | I24: Pembelian Mesin ALLWIN 2512GS UV FLATBED RICOH ke Aneka Warna Indah, PT | J24: =IF(K24=0,"",VLOOKUP(K24,Tarkun,2,0)) -> PPN Masukan | K24: 11600 | M24: =IF(L24=0," ",(VLOOKUP(L24,Kode!$B$10:$E$423,4,0))) | N24: 54504505 | O24: 0 | P24: =IF(K24="","",IF(AND(K24>0,$M$602=0),"Balance","Unbalance")) -> Balance
A25: =B25&K25 -> 121100 | B25: =IF(ERR=TRUE,COUNTIF($K$10:K25,K25),0) -> 1 | C25: =D25&M25 -> 1H-001 | D25: =IF(ERR=FALSE,0,COUNTIF($M$10:M25,M25)) -> 1 | F25: 46051 | G25: 5 | H25: 04002600004962829 | I25: Pembelian Mesin ALLWIN 2512GS UV FLATBED RICOH ke Aneka Warna Indah, PT | J25: =IF(K25=0,"",VLOOKUP(K25,Tarkun,2,0)) -> Hutang Dagang | K25: 21100 | L25: Aneka Warna Indah, PT | M25: =IF(L25=0," ",(VLOOKUP(L25,Kode!$B$10:$E$423,4,0))) -> H-001 | O25: 350000001 | P25: =IF(K25="","",IF(AND(K25>0,$M$602=0),"Balance","Unbalance")) -> Balance
A26: =B26&K26 -> 211700 | B26: =IF(ERR=TRUE,COUNTIF($K$10:K26,K26),0) -> 2 | C26: =D26&M26 -> 16 | D26: =IF(ERR=FALSE,0,COUNTIF($M$10:M26,M26)) -> 16 | F26: 46051 | G26: 5 | H26: 04002600004962829 | I26: Pembelian Mesin ALLWIN 2512GS UV FLATBED RICOH ke Aneka Warna Indah, PT | J26: =IF(K26=0,"",VLOOKUP(K26,Tarkun,2,0)) -> Uang Muka Pembelian | K26: 11700 | M26: =IF(L26=0," ",(VLOOKUP(L26,Kode!$B$10:$E$423,4,0))) | O26: 200000000 | P26: =IF(K26="","",IF(AND(K26>0,$M$602=0),"Balance","Unbalance")) -> Balance
A27: =B27&K27 -> 211600 | B27: =IF(ERR=TRUE,COUNTIF($K$10:K27,K27),0) -> 2 | C27: =D27&M27 -> 17 | D27: =IF(ERR=FALSE,0,COUNTIF($M$10:M27,M27)) -> 17 | F27: 46051 | G27: 5 | H27: 04002600007083162 | I27: Pembelian BB ke Aneka Warna Indah, PT | J27: =IF(K27=0,"",VLOOKUP(K27,Tarkun,2,0)) -> PPN Masukan | K27: 11600 | M27: =IF(L27=0," ",(VLOOKUP(L27,Kode!$B$10:$E$423,4,0))) | N27: 1557838 | O27: 0 | P27: =IF(K27="","",IF(AND(K27>0,$M$602=0),"Balance","Unbalance")) -> Balance
A28: =B28&K28 -> 153000 | B28: =IF(ERR=TRUE,COUNTIF($K$10:K28,K28),0) -> 1 | C28: =D28&M28 -> 18 | D28: =IF(ERR=FALSE,0,COUNTIF($M$10:M28,M28)) -> 18 | F28: 46051 | G28: 5 | H28: 04002600007083162 | I28: Pembelian BB ke Aneka Warna Indah, PT | J28: =IF(K28=0,"",VLOOKUP(K28,Tarkun,2,0)) -> Pembelian Bahan Baku | K28: 53000 | M28: =IF(L28=0," ",(VLOOKUP(L28,Kode!$B$10:$E$423,4,0))) | N28: 14162162 | O28: 0 | P28: =IF(K28="","",IF(AND(K28>0,$M$602=0),"Balance","Unbalance")) -> Balance
A29: =B29&K29 -> 221100 | B29: =IF(ERR=TRUE,COUNTIF($K$10:K29,K29),0) -> 2 | C29: =D29&M29 -> 2H-001 | D29: =IF(ERR=FALSE,0,COUNTIF($M$10:M29,M29)) -> 2 | F29: 46051 | G29: 5 | H29: 04002600007083162 | I29: Pembelian BB ke Aneka Warna Indah, PT | J29: =IF(K29=0,"",VLOOKUP(K29,Tarkun,2,0)) -> Hutang Dagang | K29: 21100 | L29: Aneka Warna Indah, PT | M29: =IF(L29=0," ",(VLOOKUP(L29,Kode!$B$10:$E$423,4,0))) -> H-001 | O29: 15720000 | P29: =IF(K29="","",IF(AND(K29>0,$M$602=0),"Balance","Unbalance")) -> Balance
A30: =B30&K30 -> 0 | B30: =IF(ERR=TRUE,COUNTIF($K$10:K30,K30),0) -> 0 | C30: =D30&M30 -> 19 | D30: =IF(ERR=FALSE,0,COUNTIF($M$10:M30,M30)) -> 19 | F30: 46051 | G30: 5 | J30: =IF(K30=0,"",VLOOKUP(K30,Tarkun,2,0)) | M30: =IF(L30=0," ",(VLOOKUP(L30,Kode!$B$10:$E$423,4,0))) | O30: 0 | P30: =IF(K30="","",IF(AND(K30>0,$M$602=0),"Balance","Unbalance"))
A31: =B31&K31 -> 0 | B31: =IF(ERR=TRUE,COUNTIF($K$10:K31,K31),0) -> 0 | C31: =D31&M31 -> 20 | D31: =IF(ERR=FALSE,0,COUNTIF($M$10:M31,M31)) -> 20 | F31: 46051 | G31: 5 | J31: =IF(K31=0,"",VLOOKUP(K31,Tarkun,2,0)) | M31: =IF(L31=0," ",(VLOOKUP(L31,Kode!$B$10:$E$423,4,0))) | O31: 0 | P31: =IF(K31="","",IF(AND(K31>0,$M$602=0),"Balance","Unbalance"))
A32: =B32&K32 -> 0 | B32: =IF(ERR=TRUE,COUNTIF($K$10:K32,K32),0) -> 0 | C32: =D32&M32 -> 21 | D32: =IF(ERR=FALSE,0,COUNTIF($M$10:M32,M32)) -> 21 | F32: 46051 | J32: =IF(K32=0,"",VLOOKUP(K32,Tarkun,2,0)) | M32: =IF(L32=0," ",(VLOOKUP(L32,Kode!$B$10:$E$423,4,0))) | O32: 0 | P32: =IF(K32="","",IF(AND(K32>0,$M$602=0),"Balance","Unbalance"))
A33: =B33&K33 -> 511100 | B33: =IF(ERR=TRUE,COUNTIF($K$10:K33,K33),0) -> 5 | C33: =D33&M33 -> 22 | D33: =IF(ERR=FALSE,0,COUNTIF($M$10:M33,M33)) -> 22 | F33: 46023 | G33: 6 | I33: Penjualan Retail | J33: =IF(K33=0,"",VLOOKUP(K33,Tarkun,2,0)) -> Kas | K33: 11100 | M33: =IF(L33=0," ",(VLOOKUP(L33,Kode!$B$10:$E$423,4,0))) | N33: 24833800 | P33: =IF(K33="","",IF(AND(K33>0,$M$602=0),"Balance","Unbalance")) -> Balance
A34: =B34&K34 -> 422105 | B34: =IF(ERR=TRUE,COUNTIF($K$10:K34,K34),0) -> 4 | C34: =D34&M34 -> 23 | D34: =IF(ERR=FALSE,0,COUNTIF($M$10:M34,M34)) -> 23 | F34: 46026 | G34: 6 | I34: Penjualan Retail | J34: =IF(K34=0,"",VLOOKUP(K34,Tarkun,2,0)) -> PPN Keluaran | K34: 22105 | M34: =IF(L34=0," ",(VLOOKUP(L34,Kode!$B$10:$E$423,4,0))) | O34: 2461007.2 | P34: =IF(K34="","",IF(AND(K34>0,$M$602=0),"Balance","Unbalance")) -> Balance
A35: =B35&K35 -> 441000 | B35: =IF(ERR=TRUE,COUNTIF($K$10:K35,K35),0) -> 4 | C35: =D35&M35 -> 24 | D35: =IF(ERR=FALSE,0,COUNTIF($M$10:M35,M35)) -> 24 | F35: 46027 | G35: 6 | I35: Penjualan Retail | J35: =IF(K35=0,"",VLOOKUP(K35,Tarkun,2,0)) -> Penjualan Barang | K35: 41000 | M35: =IF(L35=0," ",(VLOOKUP(L35,Kode!$B$10:$E$423,4,0))) | O35: 22372793 | P35: =IF(K35="","",IF(AND(K35>0,$M$602=0),"Balance","Unbalance")) -> Balance
A36: =B36&K36 -> 111102 | B36: =IF(ERR=TRUE,COUNTIF($K$10:K36,K36),0) -> 1 | C36: =D36&M36 -> 25 | D36: =IF(ERR=FALSE,0,COUNTIF($M$10:M36,M36)) -> 25 | F36: 46034 | G36: 6 | H36: 04002600002181848 | I36: Penjualan ke Artindo Grafika Printing, PT | J36: =IF(K36=0,"",VLOOKUP(K36,Tarkun,2,0)) -> Piutang Dagang | K36: 11102 | M36: =IF(L36=0," ",(VLOOKUP(L36,Kode!$B$10:$E$423,4,0))) | N36: 432781785 | P36: =IF(K36="","",IF(AND(K36>0,$M$602=0),"Balance","Unbalance")) -> Balance
A37: =B37&K37 -> 522105 | B37: =IF(ERR=TRUE,COUNTIF($K$10:K37,K37),0) -> 5 | C37: =D37&M37 -> 26 | D37: =IF(ERR=FALSE,0,COUNTIF($M$10:M37,M37)) -> 26 | F37: 46035 | G37: 6 | H37: 04002600002181848 | I37: Penjualan ke Artindo Grafika Printing, PT | J37: =IF(K37=0,"",VLOOKUP(K37,Tarkun,2,0)) -> PPN Keluaran | K37: 22105 | M37: =IF(L37=0," ",(VLOOKUP(L37,Kode!$B$10:$E$423,4,0))) | O37: 42888285 | P37: =IF(K37="","",IF(AND(K37>0,$M$602=0),"Balance","Unbalance")) -> Balance
A38: =B38&K38 -> 541000 | B38: =IF(ERR=TRUE,COUNTIF($K$10:K38,K38),0) -> 5 | C38: =D38&M38 -> 27 | D38: =IF(ERR=FALSE,0,COUNTIF($M$10:M38,M38)) -> 27 | F38: 46036 | G38: 6 | H38: 04002600002181848 | I38: Penjualan ke Artindo Grafika Printing, PT | J38: =IF(K38=0,"",VLOOKUP(K38,Tarkun,2,0)) -> Penjualan Barang | K38: 41000 | M38: =IF(L38=0," ",(VLOOKUP(L38,Kode!$B$10:$E$423,4,0))) | O38: 389893500 | P38: =IF(K38="","",IF(AND(K38>0,$M$602=0),"Balance","Unbalance")) -> Balance
A39: =B39&K39 -> 211102 | B39: =IF(ERR=TRUE,COUNTIF($K$10:K39,K39),0) -> 2 | C39: =D39&M39 -> 28 | D39: =IF(ERR=FALSE,0,COUNTIF($M$10:M39,M39)) -> 28 | F39: 46037 | G39: 6 | H39: 04002600002187886 | I39: Penjualan ke Artindo Grafika Printing, PT | J39: =IF(K39=0,"",VLOOKUP(K39,Tarkun,2,0)) -> Piutang Dagang | K39: 11102 | M39: =IF(L39=0," ",(VLOOKUP(L39,Kode!$B$10:$E$423,4,0))) | N39: 92157750 | P39: =IF(K39="","",IF(AND(K39>0,$M$602=0),"Balance","Unbalance")) -> Balance
A40: =B40&K40 -> 622105 | B40: =IF(ERR=TRUE,COUNTIF($K$10:K40,K40),0) -> 6 | C40: =D40&M40 -> 29 | D40: =IF(ERR=FALSE,0,COUNTIF($M$10:M40,M40)) -> 29 | F40: 46038 | G40: 6 | H40: 04002600002187886 | I40: Penjualan ke Artindo Grafika Printing, PT | J40: =IF(K40=0,"",VLOOKUP(K40,Tarkun,2,0)) -> PPN Keluaran | K40: 22105 | M40: =IF(L40=0," ",(VLOOKUP(L40,Kode!$B$10:$E$423,4,0))) | O40: 9132750 | P40: =IF(K40="","",IF(AND(K40>0,$M$602=0),"Balance","Unbalance")) -> Balance
A41: =B41&K41 -> 641000 | B41: =IF(ERR=TRUE,COUNTIF($K$10:K41,K41),0) -> 6 | C41: =D41&M41 -> 30 | D41: =IF(ERR=FALSE,0,COUNTIF($M$10:M41,M41)) -> 30 | F41: 46039 | G41: 6 | H41: 04002600002187886 | I41: Penjualan ke Artindo Grafika Printing, PT | J41: =IF(K41=0,"",VLOOKUP(K41,Tarkun,2,0)) -> Penjualan Barang | K41: 41000 | M41: =IF(L41=0," ",(VLOOKUP(L41,Kode!$B$10:$E$423,4,0))) | O41: 83025000 | P41: =IF(K41="","",IF(AND(K41>0,$M$602=0),"Balance","Unbalance")) -> Balance
...

Sheet Bk Piutang
A1: ='Data GL'!E6 -> CV. SPEKTRA DIGITAL ARTWORK
A2: ='Data GL'!E4 -> PERCETAKAN
A3: ='Data GL'!E5 -> JL. Prof Dr. Yohannes 1099 YK
A5: BUKU BESAR PIUTANG DAGANG
A6: =CONCATENATE('Data GL'!E7," -"," TAHUN"," ",'Data GL'!E8) -> Jan - TAHUN 2026
A8: Kode Pembantu | D8: =IF(F8=0," ",(VLOOKUP(F8,Kode!$B$10:$E$188,4,0))) -> #N/A | F8: Artindo Grafika Printing, PT
A10: No | B10: Tanggal | D10: Bukti | E10: Keterangan | F10: Debet | G10: Kredit | H10: Saldo
E11: Saldo Awal | F11: =VLOOKUP(D8,Kode!$E$10:$F$412,2,FALSE) -> #N/A | G11: 0 | H11: =SUM(F11:G11) -> #N/A
A12: =A11+1 -> 1 | B12: =IF(ISERROR(VLOOKUP(A12&D$8,JU_KODE,4,FALSE)=TRUE),"",VLOOKUP(A12&D$8,JU_KODE,4,FALSE)) | C12: =IF(ISERROR(VLOOKUP(A12&D$8,JU_KODE,5,FALSE)=TRUE),"",VLOOKUP(A12&D$8,JU_KODE,5,FALSE)) | D12: =IF(ISERROR(VLOOKUP(A12&D$8,JU_KODE,6,FALSE)=TRUE),"",VLOOKUP(A12&D$8,JU_KODE,6,FALSE)) | E12: =IF(ISERROR(VLOOKUP(A12&D$8,JU_KODE,7,FALSE)=TRUE),"",VLOOKUP(A12&D$8,JU_KODE,7,FALSE)) | F12: =IF(ISERROR(VLOOKUP(A12&D$8,JU_KODE,12,FALSE)=TRUE),"",VLOOKUP(A12&D$8,JU_KODE,12,FALSE)) | G12: =IF(ISERROR(VLOOKUP(A12&D$8,JU_KODE,13,FALSE)=TRUE),"",VLOOKUP(A12&D$8,JU_KODE,13,FALSE)) | H12: =IF(OR(ERR=FALSE,AND(F12="",G12="")),0,$F$11+SUM($F$12:F12)-SUM($G$12:G12)) -> 0
A13: =A12+1 -> 2 | B13: =IF(ISERROR(VLOOKUP(A13&D$8,JU_KODE,4,FALSE)=TRUE),"",VLOOKUP(A13&D$8,JU_KODE,4,FALSE)) | C13: =IF(ISERROR(VLOOKUP(A13&D$8,JU_KODE,5,FALSE)=TRUE),"",VLOOKUP(A13&D$8,JU_KODE,5,FALSE)) | D13: =IF(ISERROR(VLOOKUP(A13&D$8,JU_KODE,6,FALSE)=TRUE),"",VLOOKUP(A13&D$8,JU_KODE,6,FALSE)) | E13: =IF(ISERROR(VLOOKUP(A13&D$8,JU_KODE,7,FALSE)=TRUE),"",VLOOKUP(A13&D$8,JU_KODE,7,FALSE)) | F13: =IF(ISERROR(VLOOKUP(A13&D$8,JU_KODE,12,FALSE)=TRUE),"",VLOOKUP(A13&D$8,JU_KODE,12,FALSE)) | G13: =IF(ISERROR(VLOOKUP(A13&D$8,JU_KODE,13,FALSE)=TRUE),"",VLOOKUP(A13&D$8,JU_KODE,13,FALSE)) | H13: =IF(OR(ERR=FALSE,AND(F13="",G13="")),0,$F$11+SUM($F$12:F13)-SUM($G$12:G13)) -> 0
A14: =A13+1 -> 3 | B14: =IF(ISERROR(VLOOKUP(A14&D$8,JU_KODE,4,FALSE)=TRUE),"",VLOOKUP(A14&D$8,JU_KODE,4,FALSE)) | C14: =IF(ISERROR(VLOOKUP(A14&D$8,JU_KODE,5,FALSE)=TRUE),"",VLOOKUP(A14&D$8,JU_KODE,5,FALSE)) | D14: =IF(ISERROR(VLOOKUP(A14&D$8,JU_KODE,6,FALSE)=TRUE),"",VLOOKUP(A14&D$8,JU_KODE,6,FALSE)) | E14: =IF(ISERROR(VLOOKUP(A14&D$8,JU_KODE,7,FALSE)=TRUE),"",VLOOKUP(A14&D$8,JU_KODE,7,FALSE)) | F14: =IF(ISERROR(VLOOKUP(A14&D$8,JU_KODE,12,FALSE)=TRUE),"",VLOOKUP(A14&D$8,JU_KODE,12,FALSE)) | G14: =IF(ISERROR(VLOOKUP(A14&D$8,JU_KODE,13,FALSE)=TRUE),"",VLOOKUP(A14&D$8,JU_KODE,13,FALSE)) | H14: =IF(OR(ERR=FALSE,AND(F14="",G14="")),0,$F$11+SUM($F$12:F14)-SUM($G$12:G14)) -> 0
A15: =A14+1 -> 4 | B15: =IF(ISERROR(VLOOKUP(A15&D$8,JU_KODE,4,FALSE)=TRUE),"",VLOOKUP(A15&D$8,JU_KODE,4,FALSE)) | C15: =IF(ISERROR(VLOOKUP(A15&D$8,JU_KODE,5,FALSE)=TRUE),"",VLOOKUP(A15&D$8,JU_KODE,5,FALSE)) | D15: =IF(ISERROR(VLOOKUP(A15&D$8,JU_KODE,6,FALSE)=TRUE),"",VLOOKUP(A15&D$8,JU_KODE,6,FALSE)) | E15: =IF(ISERROR(VLOOKUP(A15&D$8,JU_KODE,7,FALSE)=TRUE),"",VLOOKUP(A15&D$8,JU_KODE,7,FALSE)) | F15: =IF(ISERROR(VLOOKUP(A15&D$8,JU_KODE,12,FALSE)=TRUE),"",VLOOKUP(A15&D$8,JU_KODE,12,FALSE)) | G15: =IF(ISERROR(VLOOKUP(A15&D$8,JU_KODE,13,FALSE)=TRUE),"",VLOOKUP(A15&D$8,JU_KODE,13,FALSE)) | H15: =IF(OR(ERR=FALSE,AND(F15="",G15="")),0,$F$11+SUM($F$12:F15)-SUM($G$12:G15)) -> 0
A16: =A15+1 -> 5 | B16: =IF(ISERROR(VLOOKUP(A16&D$8,JU_KODE,4,FALSE)=TRUE),"",VLOOKUP(A16&D$8,JU_KODE,4,FALSE)) | C16: =IF(ISERROR(VLOOKUP(A16&D$8,JU_KODE,5,FALSE)=TRUE),"",VLOOKUP(A16&D$8,JU_KODE,5,FALSE)) | D16: =IF(ISERROR(VLOOKUP(A16&D$8,JU_KODE,6,FALSE)=TRUE),"",VLOOKUP(A16&D$8,JU_KODE,6,FALSE)) | E16: =IF(ISERROR(VLOOKUP(A16&D$8,JU_KODE,7,FALSE)=TRUE),"",VLOOKUP(A16&D$8,JU_KODE,7,FALSE)) | F16: =IF(ISERROR(VLOOKUP(A16&D$8,JU_KODE,12,FALSE)=TRUE),"",VLOOKUP(A16&D$8,JU_KODE,12,FALSE)) | G16: =IF(ISERROR(VLOOKUP(A16&D$8,JU_KODE,13,FALSE)=TRUE),"",VLOOKUP(A16&D$8,JU_KODE,13,FALSE)) | H16: =IF(OR(ERR=FALSE,AND(F16="",G16="")),0,$F$11+SUM($F$12:F16)-SUM($G$12:G16)) -> 0
A17: =A16+1 -> 6 | B17: =IF(ISERROR(VLOOKUP(A17&D$8,JU_KODE,4,FALSE)=TRUE),"",VLOOKUP(A17&D$8,JU_KODE,4,FALSE)) | C17: =IF(ISERROR(VLOOKUP(A17&D$8,JU_KODE,5,FALSE)=TRUE),"",VLOOKUP(A17&D$8,JU_KODE,5,FALSE)) | D17: =IF(ISERROR(VLOOKUP(A17&D$8,JU_KODE,6,FALSE)=TRUE),"",VLOOKUP(A17&D$8,JU_KODE,6,FALSE)) | E17: =IF(ISERROR(VLOOKUP(A17&D$8,JU_KODE,7,FALSE)=TRUE),"",VLOOKUP(A17&D$8,JU_KODE,7,FALSE)) | F17: =IF(ISERROR(VLOOKUP(A17&D$8,JU_KODE,12,FALSE)=TRUE),"",VLOOKUP(A17&D$8,JU_KODE,12,FALSE)) | G17: =IF(ISERROR(VLOOKUP(A17&D$8,JU_KODE,13,FALSE)=TRUE),"",VLOOKUP(A17&D$8,JU_KODE,13,FALSE)) | H17: =IF(OR(ERR=FALSE,AND(F17="",G17="")),0,$F$11+SUM($F$12:F17)-SUM($G$12:G17)) -> 0
A18: =A17+1 -> 7 | B18: =IF(ISERROR(VLOOKUP(A18&D$8,JU_KODE,4,FALSE)=TRUE),"",VLOOKUP(A18&D$8,JU_KODE,4,FALSE)) | C18: =IF(ISERROR(VLOOKUP(A18&D$8,JU_KODE,5,FALSE)=TRUE),"",VLOOKUP(A18&D$8,JU_KODE,5,FALSE)) | D18: =IF(ISERROR(VLOOKUP(A18&D$8,JU_KODE,6,FALSE)=TRUE),"",VLOOKUP(A18&D$8,JU_KODE,6,FALSE)) | E18: =IF(ISERROR(VLOOKUP(A18&D$8,JU_KODE,7,FALSE)=TRUE),"",VLOOKUP(A18&D$8,JU_KODE,7,FALSE)) | F18: =IF(ISERROR(VLOOKUP(A18&D$8,JU_KODE,12,FALSE)=TRUE),"",VLOOKUP(A18&D$8,JU_KODE,12,FALSE)) | G18: =IF(ISERROR(VLOOKUP(A18&D$8,JU_KODE,13,FALSE)=TRUE),"",VLOOKUP(A18&D$8,JU_KODE,13,FALSE)) | H18: =IF(OR(ERR=FALSE,AND(F18="",G18="")),0,$F$11+SUM($F$12:F18)-SUM($G$12:G18)) -> 0
A19: =A18+1 -> 8 | B19: =IF(ISERROR(VLOOKUP(A19&D$8,JU_KODE,4,FALSE)=TRUE),"",VLOOKUP(A19&D$8,JU_KODE,4,FALSE)) | C19: =IF(ISERROR(VLOOKUP(A19&D$8,JU_KODE,5,FALSE)=TRUE),"",VLOOKUP(A19&D$8,JU_KODE,5,FALSE)) | D19: =IF(ISERROR(VLOOKUP(A19&D$8,JU_KODE,6,FALSE)=TRUE),"",VLOOKUP(A19&D$8,JU_KODE,6,FALSE)) | E19: =IF(ISERROR(VLOOKUP(A19&D$8,JU_KODE,7,FALSE)=TRUE),"",VLOOKUP(A19&D$8,JU_KODE,7,FALSE)) | F19: =IF(ISERROR(VLOOKUP(A19&D$8,JU_KODE,12,FALSE)=TRUE),"",VLOOKUP(A19&D$8,JU_KODE,12,FALSE)) | G19: =IF(ISERROR(VLOOKUP(A19&D$8,JU_KODE,13,FALSE)=TRUE),"",VLOOKUP(A19&D$8,JU_KODE,13,FALSE)) | H19: =IF(OR(ERR=FALSE,AND(F19="",G19="")),0,$F$11+SUM($F$12:F19)-SUM($G$12:G19)) -> 0
A20: =A19+1 -> 9 | B20: =IF(ISERROR(VLOOKUP(A20&D$8,JU_KODE,4,FALSE)=TRUE),"",VLOOKUP(A20&D$8,JU_KODE,4,FALSE)) | C20: =IF(ISERROR(VLOOKUP(A20&D$8,JU_KODE,5,FALSE)=TRUE),"",VLOOKUP(A20&D$8,JU_KODE,5,FALSE)) | D20: =IF(ISERROR(VLOOKUP(A20&D$8,JU_KODE,6,FALSE)=TRUE),"",VLOOKUP(A20&D$8,JU_KODE,6,FALSE)) | E20: =IF(ISERROR(VLOOKUP(A20&D$8,JU_KODE,7,FALSE)=TRUE),"",VLOOKUP(A20&D$8,JU_KODE,7,FALSE)) | F20: =IF(ISERROR(VLOOKUP(A20&D$8,JU_KODE,12,FALSE)=TRUE),"",VLOOKUP(A20&D$8,JU_KODE,12,FALSE)) | G20: =IF(ISERROR(VLOOKUP(A20&D$8,JU_KODE,13,FALSE)=TRUE),"",VLOOKUP(A20&D$8,JU_KODE,13,FALSE)) | H20: =IF(OR(ERR=FALSE,AND(F20="",G20="")),0,$F$11+SUM($F$12:F20)-SUM($G$12:G20)) -> 0
A21: =A20+1 -> 10 | B21: =IF(ISERROR(VLOOKUP(A21&D$8,JU_KODE,4,FALSE)=TRUE),"",VLOOKUP(A21&D$8,JU_KODE,4,FALSE)) | C21: =IF(ISERROR(VLOOKUP(A21&D$8,JU_KODE,5,FALSE)=TRUE),"",VLOOKUP(A21&D$8,JU_KODE,5,FALSE)) | D21: =IF(ISERROR(VLOOKUP(A21&D$8,JU_KODE,6,FALSE)=TRUE),"",VLOOKUP(A21&D$8,JU_KODE,6,FALSE)) | E21: =IF(ISERROR(VLOOKUP(A21&D$8,JU_KODE,7,FALSE)=TRUE),"",VLOOKUP(A21&D$8,JU_KODE,7,FALSE)) | F21: =IF(ISERROR(VLOOKUP(A21&D$8,JU_KODE,12,FALSE)=TRUE),"",VLOOKUP(A21&D$8,JU_KODE,12,FALSE)) | G21: =IF(ISERROR(VLOOKUP(A21&D$8,JU_KODE,13,FALSE)=TRUE),"",VLOOKUP(A21&D$8,JU_KODE,13,FALSE)) | H21: =IF(OR(ERR=FALSE,AND(F21="",G21="")),0,$F$11+SUM($F$12:F21)-SUM($G$12:G21)) -> 0
A22: =A21+1 -> 11 | B22: =IF(ISERROR(VLOOKUP(A22&D$8,JU_KODE,4,FALSE)=TRUE),"",VLOOKUP(A22&D$8,JU_KODE,4,FALSE)) | C22: =IF(ISERROR(VLOOKUP(A22&D$8,JU_KODE,5,FALSE)=TRUE),"",VLOOKUP(A22&D$8,JU_KODE,5,FALSE)) | D22: =IF(ISERROR(VLOOKUP(A22&D$8,JU_KODE,6,FALSE)=TRUE),"",VLOOKUP(A22&D$8,JU_KODE,6,FALSE)) | E22: =IF(ISERROR(VLOOKUP(A22&D$8,JU_KODE,7,FALSE)=TRUE),"",VLOOKUP(A22&D$8,JU_KODE,7,FALSE)) | F22: =IF(ISERROR(VLOOKUP(A22&D$8,JU_KODE,12,FALSE)=TRUE),"",VLOOKUP(A22&D$8,JU_KODE,12,FALSE)) | G22: =IF(ISERROR(VLOOKUP(A22&D$8,JU_KODE,13,FALSE)=TRUE),"",VLOOKUP(A22&D$8,JU_KODE,13,FALSE)) | H22: =IF(OR(ERR=FALSE,AND(F22="",G22="")),0,$F$11+SUM($F$12:F22)-SUM($G$12:G22)) -> 0
A23: =A22+1 -> 12 | B23: =IF(ISERROR(VLOOKUP(A23&D$8,JU_KODE,4,FALSE)=TRUE),"",VLOOKUP(A23&D$8,JU_KODE,4,FALSE)) | C23: =IF(ISERROR(VLOOKUP(A23&D$8,JU_KODE,5,FALSE)=TRUE),"",VLOOKUP(A23&D$8,JU_KODE,5,FALSE)) | D23: =IF(ISERROR(VLOOKUP(A23&D$8,JU_KODE,6,FALSE)=TRUE),"",VLOOKUP(A23&D$8,JU_KODE,6,FALSE)) | E23: =IF(ISERROR(VLOOKUP(A23&D$8,JU_KODE,7,FALSE)=TRUE),"",VLOOKUP(A23&D$8,JU_KODE,7,FALSE)) | F23: =IF(ISERROR(VLOOKUP(A23&D$8,JU_KODE,12,FALSE)=TRUE),"",VLOOKUP(A23&D$8,JU_KODE,12,FALSE)) | G23: =IF(ISERROR(VLOOKUP(A23&D$8,JU_KODE,13,FALSE)=TRUE),"",VLOOKUP(A23&D$8,JU_KODE,13,FALSE)) | H23: =IF(OR(ERR=FALSE,AND(F23="",G23="")),0,$F$11+SUM($F$12:F23)-SUM($G$12:G23)) -> 0
... A223: =A222+1 -> 212 | B223: =IF(ISERROR(VLOOKUP(A223&D$8,JU_KODE,4,FALSE)=TRUE),"",VLOOKUP(A223&D$8,JU_KODE,4,FALSE)) | C223: =IF(ISERROR(VLOOKUP(A223&D$8,JU_KODE,5,FALSE)=TRUE),"",VLOOKUP(A223&D$8,JU_KODE,5,FALSE)) | D223: =IF(ISERROR(VLOOKUP(A223&D$8,JU_KODE,6,FALSE)=TRUE),"",VLOOKUP(A223&D$8,JU_KODE,6,FALSE)) | E223: =IF(ISERROR(VLOOKUP(A223&D$8,JU_KODE,7,FALSE)=TRUE),"",VLOOKUP(A223&D$8,JU_KODE,7,FALSE)) | F223: =IF(ISERROR(VLOOKUP(A223&D$8,JU_KODE,12,FALSE)=TRUE),"",VLOOKUP(A223&D$8,JU_KODE,12,FALSE)) | G223: =IF(ISERROR(VLOOKUP(A223&D$8,JU_KODE,13,FALSE)=TRUE),"",VLOOKUP(A223&D$8,JU_KODE,13,FALSE)) | H223: =IF(OR(ERR=FALSE,AND(F223="",G223="")),0,$F$11+SUM($F$12:F223)-SUM($G$12:G223)) -> 0

Sheet Bk Hutang
A1: ='Data GL'!E6 -> CV. SPEKTRA DIGITAL ARTWORK
A2: ='Data GL'!E4 -> PERCETAKAN
A3: ='Data GL'!E5 -> JL. Prof Dr. Yohannes 1099 YK
A5: BUKU BESAR HUTANG DAGANG
A6: =CONCATENATE('Data GL'!E7," -"," TAHUN"," ",'Data GL'!E8) -> Jan - TAHUN 2026
A8: Kode Pembantu | D8: =IF(F8=0," ",(VLOOKUP(F8,Kode!$B$10:$E$188,4,0))) -> H-003 | F8: Jaya Sejahtera, CV
A10: No | B10: Tanggal | D10: Bukti | E10: Keterangan | F10: Debet | G10: Kredit | H10: Saldo
E11: Saldo Awal | F11: 0 | G11: =VLOOKUP(D8,Kode!$E$10:$F$412,2,FALSE) -> 3685010 | H11: =SUM(F11:G11) -> 3685010
A12: =A11+1 -> 1 | B12: =IF(ISERROR(VLOOKUP(A12&D$8,JU_KODE,4,FALSE)=TRUE),"",VLOOKUP(A12&D$8,JU_KODE,4,FALSE)) -> 46051 | C12: =IF(ISERROR(VLOOKUP(A12&D$8,JU_KODE,5,FALSE)=TRUE),"",VLOOKUP(A12&D$8,JU_KODE,5,FALSE)) -> 9 | D12: =IF(ISERROR(VLOOKUP(A12&D$8,JU_KODE,6,FALSE)=TRUE),"",VLOOKUP(A12&D$8,JU_KODE,6,FALSE)) -> 04002600004398651 | E12: =IF(ISERROR(VLOOKUP(A12&D$8,JU_KODE,7,FALSE)=TRUE),"",VLOOKUP(A12&D$8,JU_KODE,7,FALSE)) -> Pembelian BB ke Jaya Sejahtera, CV | F12: =IF(ISERROR(VLOOKUP(A12&D$8,JU_KODE,12,FALSE)=TRUE),"",VLOOKUP(A12&D$8,JU_KODE,12,FALSE)) -> 0 | G12: =IF(ISERROR(VLOOKUP(A12&D$8,JU_KODE,13,FALSE)=TRUE),"",VLOOKUP(A12&D$8,JU_KODE,13,FALSE)) -> 4725000 | H12: =IF(OR(ERR=FALSE,AND(F12="",G12="")),0,$G$11-SUM($F$12:F12)+SUM($G$12:G12)) -> 8410010
A13: =A12+1 -> 2 | B13: =IF(ISERROR(VLOOKUP(A13&D$8,JU_KODE,4,FALSE)=TRUE),"",VLOOKUP(A13&D$8,JU_KODE,4,FALSE)) -> 46051 | C13: =IF(ISERROR(VLOOKUP(A13&D$8,JU_KODE,5,FALSE)=TRUE),"",VLOOKUP(A13&D$8,JU_KODE,5,FALSE)) -> 12 | D13: =IF(ISERROR(VLOOKUP(A13&D$8,JU_KODE,6,FALSE)=TRUE),"",VLOOKUP(A13&D$8,JU_KODE,6,FALSE)) -> 0 | E13: =IF(ISERROR(VLOOKUP(A13&D$8,JU_KODE,7,FALSE)=TRUE),"",VLOOKUP(A13&D$8,JU_KODE,7,FALSE)) -> Bayar Hutang Jaya Sejahtera 12/12'2025 | F13: =IF(ISERROR(VLOOKUP(A13&D$8,JU_KODE,12,FALSE)=TRUE),"",VLOOKUP(A13&D$8,JU_KODE,12,FALSE)) -> 3685000 | G13: =IF(ISERROR(VLOOKUP(A13&D$8,JU_KODE,13,FALSE)=TRUE),"",VLOOKUP(A13&D$8,JU_KODE,13,FALSE)) -> 0 | H13: =IF(OR(ERR=FALSE,AND(F13="",G13="")),0,$G$11-SUM($F$12:F13)+SUM($G$12:G13)) -> 4725010
A14: =A13+1 -> 3 | B14: =IF(ISERROR(VLOOKUP(A14&D$8,JU_KODE,4,FALSE)=TRUE),"",VLOOKUP(A14&D$8,JU_KODE,4,FALSE)) -> 46051 | C14: =IF(ISERROR(VLOOKUP(A14&D$8,JU_KODE,5,FALSE)=TRUE),"",VLOOKUP(A14&D$8,JU_KODE,5,FALSE)) -> 19 | D14: =IF(ISERROR(VLOOKUP(A14&D$8,JU_KODE,6,FALSE)=TRUE),"",VLOOKUP(A14&D$8,JU_KODE,6,FALSE)) -> 04002600015931055 | E14: =IF(ISERROR(VLOOKUP(A14&D$8,JU_KODE,7,FALSE)=TRUE),"",VLOOKUP(A14&D$8,JU_KODE,7,FALSE)) -> Pembelian BB ke Jaya Sejahtera, CV | F14: =IF(ISERROR(VLOOKUP(A14&D$8,JU_KODE,12,FALSE)=TRUE),"",VLOOKUP(A14&D$8,JU_KODE,12,FALSE)) -> 0 | G14: =IF(ISERROR(VLOOKUP(A14&D$8,JU_KODE,13,FALSE)=TRUE),"",VLOOKUP(A14&D$8,JU_KODE,13,FALSE)) -> 4790000 | H14: =IF(OR(ERR=FALSE,AND(F14="",G14="")),0,$G$11-SUM($F$12:F14)+SUM($G$12:G14)) -> 9515010
A15: =A14+1 -> 4 | B15: =IF(ISERROR(VLOOKUP(A15&D$8,JU_KODE,4,FALSE)=TRUE),"",VLOOKUP(A15&D$8,JU_KODE,4,FALSE)) -> 46051 | C15: =IF(ISERROR(VLOOKUP(A15&D$8,JU_KODE,5,FALSE)=TRUE),"",VLOOKUP(A15&D$8,JU_KODE,5,FALSE)) -> 27 | D15: =IF(ISERROR(VLOOKUP(A15&D$8,JU_KODE,6,FALSE)=TRUE),"",VLOOKUP(A15&D$8,JU_KODE,6,FALSE)) -> 04002600023320688 | E15: =IF(ISERROR(VLOOKUP(A15&D$8,JU_KODE,7,FALSE)=TRUE),"",VLOOKUP(A15&D$8,JU_KODE,7,FALSE)) -> Pembelian BB ke Jaya Sejahtera, CV | F15: =IF(ISERROR(VLOOKUP(A15&D$8,JU_KODE,12,FALSE)=TRUE),"",VLOOKUP(A15&D$8,JU_KODE,12,FALSE)) -> 0 | G15: =IF(ISERROR(VLOOKUP(A15&D$8,JU_KODE,13,FALSE)=TRUE),"",VLOOKUP(A15&D$8,JU_KODE,13,FALSE)) -> 6535000 | H15: =IF(OR(ERR=FALSE,AND(F15="",G15="")),0,$G$11-SUM($F$12:F15)+SUM($G$12:G15)) -> 16050010
A16: =A15+1 -> 5 | B16: =IF(ISERROR(VLOOKUP(A16&D$8,JU_KODE,4,FALSE)=TRUE),"",VLOOKUP(A16&D$8,JU_KODE,4,FALSE)) -> 46051 | C16: =IF(ISERROR(VLOOKUP(A16&D$8,JU_KODE,5,FALSE)=TRUE),"",VLOOKUP(A16&D$8,JU_KODE,5,FALSE)) -> 28 | D16: =IF(ISERROR(VLOOKUP(A16&D$8,JU_KODE,6,FALSE)=TRUE),"",VLOOKUP(A16&D$8,JU_KODE,6,FALSE)) -> 04002600023320809 | E16: =IF(ISERROR(VLOOKUP(A16&D$8,JU_KODE,7,FALSE)=TRUE),"",VLOOKUP(A16&D$8,JU_KODE,7,FALSE)) -> Pembelian BB ke Jaya Sejahtera, CV | F16: =IF(ISERROR(VLOOKUP(A16&D$8,JU_KODE,12,FALSE)=TRUE),"",VLOOKUP(A16&D$8,JU_KODE,12,FALSE)) -> 0 | G16: =IF(ISERROR(VLOOKUP(A16&D$8,JU_KODE,13,FALSE)=TRUE),"",VLOOKUP(A16&D$8,JU_KODE,13,FALSE)) -> 460000 | H16: =IF(OR(ERR=FALSE,AND(F16="",G16="")),0,$G$11-SUM($F$12:F16)+SUM($G$12:G16)) -> 16510010
A17: =A16+1 -> 6 | B17: =IF(ISERROR(VLOOKUP(A17&D$8,JU_KODE,4,FALSE)=TRUE),"",VLOOKUP(A17&D$8,JU_KODE,4,FALSE)) | C17: =IF(ISERROR(VLOOKUP(A17&D$8,JU_KODE,5,FALSE)=TRUE),"",VLOOKUP(A17&D$8,JU_KODE,5,FALSE)) | D17: =IF(ISERROR(VLOOKUP(A17&D$8,JU_KODE,6,FALSE)=TRUE),"",VLOOKUP(A17&D$8,JU_KODE,6,FALSE)) | E17: =IF(ISERROR(VLOOKUP(A17&D$8,JU_KODE,7,FALSE)=TRUE),"",VLOOKUP(A17&D$8,JU_KODE,7,FALSE)) | F17: =IF(ISERROR(VLOOKUP(A17&D$8,JU_KODE,12,FALSE)=TRUE),"",VLOOKUP(A17&D$8,JU_KODE,12,FALSE)) | G17: =IF(ISERROR(VLOOKUP(A17&D$8,JU_KODE,13,FALSE)=TRUE),"",VLOOKUP(A17&D$8,JU_KODE,13,FALSE)) | H17: =IF(OR(ERR=FALSE,AND(F17="",G17="")),0,$G$11-SUM($F$12:F17)+SUM($G$12:G17)) -> 0
A18: =A17+1 -> 7 | B18: =IF(ISERROR(VLOOKUP(A18&D$8,JU_KODE,4,FALSE)=TRUE),"",VLOOKUP(A18&D$8,JU_KODE,4,FALSE)) | C18: =IF(ISERROR(VLOOKUP(A18&D$8,JU_KODE,5,FALSE)=TRUE),"",VLOOKUP(A18&D$8,JU_KODE,5,FALSE)) | D18: =IF(ISERROR(VLOOKUP(A18&D$8,JU_KODE,6,FALSE)=TRUE),"",VLOOKUP(A18&D$8,JU_KODE,6,FALSE)) | E18: =IF(ISERROR(VLOOKUP(A18&D$8,JU_KODE,7,FALSE)=TRUE),"",VLOOKUP(A18&D$8,JU_KODE,7,FALSE)) | F18: =IF(ISERROR(VLOOKUP(A18&D$8,JU_KODE,12,FALSE)=TRUE),"",VLOOKUP(A18&D$8,JU_KODE,12,FALSE)) | G18: =IF(ISERROR(VLOOKUP(A18&D$8,JU_KODE,13,FALSE)=TRUE),"",VLOOKUP(A18&D$8,JU_KODE,13,FALSE)) | H18: =IF(OR(ERR=FALSE,AND(F18="",G18="")),0,$G$11-SUM($F$12:F18)+SUM($G$12:G18)) -> 0
A19: =A18+1 -> 8 | B19: =IF(ISERROR(VLOOKUP(A19&D$8,JU_KODE,4,FALSE)=TRUE),"",VLOOKUP(A19&D$8,JU_KODE,4,FALSE)) | C19: =IF(ISERROR(VLOOKUP(A19&D$8,JU_KODE,5,FALSE)=TRUE),"",VLOOKUP(A19&D$8,JU_KODE,5,FALSE)) | D19: =IF(ISERROR(VLOOKUP(A19&D$8,JU_KODE,6,FALSE)=TRUE),"",VLOOKUP(A19&D$8,JU_KODE,6,FALSE)) | E19: =IF(ISERROR(VLOOKUP(A19&D$8,JU_KODE,7,FALSE)=TRUE),"",VLOOKUP(A19&D$8,JU_KODE,7,FALSE)) | F19: =IF(ISERROR(VLOOKUP(A19&D$8,JU_KODE,12,FALSE)=TRUE),"",VLOOKUP(A19&D$8,JU_KODE,12,FALSE)) | G19: =IF(ISERROR(VLOOKUP(A19&D$8,JU_KODE,13,FALSE)=TRUE),"",VLOOKUP(A19&D$8,JU_KODE,13,FALSE)) | H19: =IF(OR(ERR=FALSE,AND(F19="",G19="")),0,$G$11-SUM($F$12:F19)+SUM($G$12:G19)) -> 0
A20: =A19+1 -> 9 | B20: =IF(ISERROR(VLOOKUP(A20&D$8,JU_KODE,4,FALSE)=TRUE),"",VLOOKUP(A20&D$8,JU_KODE,4,FALSE)) | C20: =IF(ISERROR(VLOOKUP(A20&D$8,JU_KODE,5,FALSE)=TRUE),"",VLOOKUP(A20&D$8,JU_KODE,5,FALSE)) | D20: =IF(ISERROR(VLOOKUP(A20&D$8,JU_KODE,6,FALSE)=TRUE),"",VLOOKUP(A20&D$8,JU_KODE,6,FALSE)) | E20: =IF(ISERROR(VLOOKUP(A20&D$8,JU_KODE,7,FALSE)=TRUE),"",VLOOKUP(A20&D$8,JU_KODE,7,FALSE)) | F20: =IF(ISERROR(VLOOKUP(A20&D$8,JU_KODE,12,FALSE)=TRUE),"",VLOOKUP(A20&D$8,JU_KODE,12,FALSE)) | G20: =IF(ISERROR(VLOOKUP(A20&D$8,JU_KODE,13,FALSE)=TRUE),"",VLOOKUP(A20&D$8,JU_KODE,13,FALSE)) | H20: =IF(OR(ERR=FALSE,AND(F20="",G20="")),0,$G$11-SUM($F$12:F20)+SUM($G$12:G20)) -> 0
A21: =A20+1 -> 10 | B21: =IF(ISERROR(VLOOKUP(A21&D$8,JU_KODE,4,FALSE)=TRUE),"",VLOOKUP(A21&D$8,JU_KODE,4,FALSE)) | C21: =IF(ISERROR(VLOOKUP(A21&D$8,JU_KODE,5,FALSE)=TRUE),"",VLOOKUP(A21&D$8,JU_KODE,5,FALSE)) | D21: =IF(ISERROR(VLOOKUP(A21&D$8,JU_KODE,6,FALSE)=TRUE),"",VLOOKUP(A21&D$8,JU_KODE,6,FALSE)) | E21: =IF(ISERROR(VLOOKUP(A21&D$8,JU_KODE,7,FALSE)=TRUE),"",VLOOKUP(A21&D$8,JU_KODE,7,FALSE)) | F21: =IF(ISERROR(VLOOKUP(A21&D$8,JU_KODE,12,FALSE)=TRUE),"",VLOOKUP(A21&D$8,JU_KODE,12,FALSE)) | G21: =IF(ISERROR(VLOOKUP(A21&D$8,JU_KODE,13,FALSE)=TRUE),"",VLOOKUP(A21&D$8,JU_KODE,13,FALSE)) | H21: =IF(OR(ERR=FALSE,AND(F21="",G21="")),0,$G$11-SUM($F$12:F21)+SUM($G$12:G21)) -> 0
A22: =A21+1 -> 11 | B22: =IF(ISERROR(VLOOKUP(A22&D$8,JU_KODE,4,FALSE)=TRUE),"",VLOOKUP(A22&D$8,JU_KODE,4,FALSE)) | C22: =IF(ISERROR(VLOOKUP(A22&D$8,JU_KODE,5,FALSE)=TRUE),"",VLOOKUP(A22&D$8,JU_KODE,5,FALSE)) | D22: =IF(ISERROR(VLOOKUP(A22&D$8,JU_KODE,6,FALSE)=TRUE),"",VLOOKUP(A22&D$8,JU_KODE,6,FALSE)) | E22: =IF(ISERROR(VLOOKUP(A22&D$8,JU_KODE,7,FALSE)=TRUE),"",VLOOKUP(A22&D$8,JU_KODE,7,FALSE)) | F22: =IF(ISERROR(VLOOKUP(A22&D$8,JU_KODE,12,FALSE)=TRUE),"",VLOOKUP(A22&D$8,JU_KODE,12,FALSE)) | G22: =IF(ISERROR(VLOOKUP(A22&D$8,JU_KODE,13,FALSE)=TRUE),"",VLOOKUP(A22&D$8,JU_KODE,13,FALSE)) | H22: =IF(OR(ERR=FALSE,AND(F22="",G22="")),0,$G$11-SUM($F$12:F22)+SUM($G$12:G22)) -> 0
A23: =A22+1 -> 12 | B23: =IF(ISERROR(VLOOKUP(A23&D$8,JU_KODE,4,FALSE)=TRUE),"",VLOOKUP(A23&D$8,JU_KODE,4,FALSE)) | C23: =IF(ISERROR(VLOOKUP(A23&D$8,JU_KODE,5,FALSE)=TRUE),"",VLOOKUP(A23&D$8,JU_KODE,5,FALSE)) | D23: =IF(ISERROR(VLOOKUP(A23&D$8,JU_KODE,6,FALSE)=TRUE),"",VLOOKUP(A23&D$8,JU_KODE,6,FALSE)) | E23: =IF(ISERROR(VLOOKUP(A23&D$8,JU_KODE,7,FALSE)=TRUE),"",VLOOKUP(A23&D$8,JU_KODE,7,FALSE)) | F23: =IF(ISERROR(VLOOKUP(A23&D$8,JU_KODE,12,FALSE)=TRUE),"",VLOOKUP(A23&D$8,JU_KODE,12,FALSE)) | G23: =IF(ISERROR(VLOOKUP(A23&D$8,JU_KODE,13,FALSE)=TRUE),"",VLOOKUP(A23&D$8,JU_KODE,13,FALSE)) | H23: =IF(OR(ERR=FALSE,AND(F23="",G23="")),0,$G$11-SUM($F$12:F23)+SUM($G$12:G23)) -> 0
... A818: =A817+1 -> 807 | B818: =IF(ISERROR(VLOOKUP(A818&D$8,JU_KODE,4,FALSE)=TRUE),"",VLOOKUP(A818&D$8,JU_KODE,4,FALSE)) | C818: =IF(ISERROR(VLOOKUP(A818&D$8,JU_KODE,5,FALSE)=TRUE),"",VLOOKUP(A818&D$8,JU_KODE,5,FALSE)) | D818: =IF(ISERROR(VLOOKUP(A818&D$8,JU_KODE,6,FALSE)=TRUE),"",VLOOKUP(A818&D$8,JU_KODE,6,FALSE)) | E818: =IF(ISERROR(VLOOKUP(A818&D$8,JU_KODE,7,FALSE)=TRUE),"",VLOOKUP(A818&D$8,JU_KODE,7,FALSE)) | F818: =IF(ISERROR(VLOOKUP(A818&D$8,JU_KODE,12,FALSE)=TRUE),"",VLOOKUP(A818&D$8,JU_KODE,12,FALSE)) | G818: =IF(ISERROR(VLOOKUP(A818&D$8,JU_KODE,13,FALSE)=TRUE),"",VLOOKUP(A818&D$8,JU_KODE,13,FALSE)) | H818: =IF(OR(ERR=FALSE,AND(F818="",G818="")),0,$G$11-SUM($F$12:F818)+SUM($G$12:G818)) -> 0

Sheet Neraca Lajur
A1: ='Data GL'!E6 -> CV. SPEKTRA DIGITAL ARTWORK
A2: ='Data GL'!E4 -> PERCETAKAN
A3: ='Data GL'!E5 -> JL. Prof Dr. Yohannes 1099 YK
A5: NERACA LAJUR
A6: =CONCATENATE('Data GL'!E7," -"," TAHUN"," ",'Data GL'!E8) -> Jan - TAHUN 2026
A8: Kode | B8: Nama Akun | C8: Pos Saldo | D8: Neraca Saldo | F8: Pos Lapr | G8: Laba Rugi | I8: Neraca
A9: Akun | D9: Debet | E9: Kredit | G9: Debet | H9: Kredit | I9: Debet | J9: Kredit
A10: 10000 | B10: =VLOOKUP(A10,DAF_AKUN,2,FALSE) -> AKTIVA
A11: 11000 | B11: =VLOOKUP(A11,DAF_AKUN,2,FALSE) -> AKTIVA LANCAR
A12: 11100 | B12: =VLOOKUP(A12,DAF_AKUN,2,FALSE) -> Kas | C12: =VLOOKUP(A12,DAF_AKUN,3,FALSE) -> D | D12: =IF(C12="D",SUMIF(Akun!A:A,A12,Akun!F:F)+SUMIF(Jurnal!K:K,A12,Jurnal!N:N)-SUMIF(Jurnal!K:K,A12,Jurnal!O:O),0) -> 1434652025 | E12: =IF(C12="K",SUMIF(Akun!A:A,A12,Akun!G:G)-SUMIF(Jurnal!K:K,A12,Jurnal!N:N)+SUMIF(Jurnal!K:K,A12,Jurnal!O:O),0) -> 0 | F12: =VLOOKUP(A12,DAF_AKUN,4,FALSE) -> NR | G12: =IF(F12="LR",D12,0) -> 0 | H12: =IF(F12="LR",E12,0) -> 0 | I12: =IF(F12="NR",D12,0) -> 1434652025 | J12: =IF(F12="NR",E12,0) -> 0
A13: 11101 | B13: =VLOOKUP(A13,DAF_AKUN,2,FALSE) -> Bank | C13: =VLOOKUP(A13,DAF_AKUN,3,FALSE) -> D | D13: =IF(C13="D",SUMIF(Akun!A:A,A13,Akun!F:F)+SUMIF(Jurnal!K:K,A13,Jurnal!N:N)-SUMIF(Jurnal!K:K,A13,Jurnal!O:O),0) -> 0 | E13: =IF(C13="K",SUMIF(Akun!A:A,A13,Akun!G:G)-SUMIF(Jurnal!K:K,A13,Jurnal!N:N)+SUMIF(Jurnal!K:K,A13,Jurnal!O:O),0) -> 0 | F13: =VLOOKUP(A13,DAF_AKUN,4,FALSE) -> NR | G13: =IF(F13="LR",D13,0) -> 0 | H13: =IF(F13="LR",E13,0) -> 0 | I13: =IF(F13="NR",D13,0) -> 0 | J13: =IF(F13="NR",E13,0) -> 0
A14: 11102 | B14: =VLOOKUP(A14,DAF_AKUN,2,FALSE) -> Piutang Dagang | C14: =VLOOKUP(A14,DAF_AKUN,3,FALSE) -> D | D14: =IF(C14="D",SUMIF(Akun!A:A,A14,Akun!F:F)+SUMIF(Jurnal!K:K,A14,Jurnal!N:N)-SUMIF(Jurnal!K:K,A14,Jurnal!O:O),0) -> 1.2702828e+09 | E14: =IF(C14="K",SUMIF(Akun!A:A,A14,Akun!G:G)-SUMIF(Jurnal!K:K,A14,Jurnal!N:N)+SUMIF(Jurnal!K:K,A14,Jurnal!O:O),0) -> 0 | F14: =VLOOKUP(A14,DAF_AKUN,4,FALSE) -> NR | G14: =IF(F14="LR",D14,0) -> 0 | H14: =IF(F14="LR",E14,0) -> 0 | I14: =IF(F14="NR",D14,0) -> 1.2702828e+09 | J14: =IF(F14="NR",E14,0) -> 0
A15: 11103 | B15: =VLOOKUP(A15,DAF_AKUN,2,FALSE) -> Piutang Karyawan | C15: =VLOOKUP(A15,DAF_AKUN,3,FALSE) -> D | D15: =IF(C15="D",SUMIF(Akun!A:A,A15,Akun!F:F)+SUMIF(Jurnal!K:K,A15,Jurnal!N:N)-SUMIF(Jurnal!K:K,A15,Jurnal!O:O),0) -> 0 | E15: =IF(C15="K",SUMIF(Akun!A:A,A15,Akun!G:G)-SUMIF(Jurnal!K:K,A15,Jurnal!N:N)+SUMIF(Jurnal!K:K,A15,Jurnal!O:O),0) -> 0 | F15: =VLOOKUP(A15,DAF_AKUN,4,FALSE) -> NR | G15: =IF(F15="LR",D15,0) -> 0 | H15: =IF(F15="LR",E15,0) -> 0 | I15: =IF(F15="NR",D15,0) -> 0 | J15: =IF(F15="NR",E15,0) -> 0
A16: 11200 | B16: =VLOOKUP(A16,DAF_AKUN,2,FALSE) -> Persediaan Barang Jadi | C16: =VLOOKUP(A16,DAF_AKUN,3,FALSE) -> D | D16: =IF(C16="D",SUMIF(Akun!A:A,A16,Akun!F:F)+SUMIF(Jurnal!K:K,A16,Jurnal!N:N)-SUMIF(Jurnal!K:K,A16,Jurnal!O:O),0) -> 1553000000 | E16: =IF(C16="K",SUMIF(Akun!A:A,A16,Akun!G:G)-SUMIF(Jurnal!K:K,A16,Jurnal!N:N)+SUMIF(Jurnal!K:K,A16,Jurnal!O:O),0) -> 0 | F16: =VLOOKUP(A16,DAF_AKUN,4,FALSE) -> NR | G16: =IF(F16="LR",D16,0) -> 0 | H16: =IF(F16="LR",E16,0) -> 0 | I16: =IF(F16="NR",D16,0) -> 1553000000 | J16: =IF(F16="NR",E16,0) -> 0
A17: 11300 | B17: =VLOOKUP(A17,DAF_AKUN,2,FALSE) -> Persediaan Barang Proses | C17: =VLOOKUP(A17,DAF_AKUN,3,FALSE) -> D | D17: =IF(C17="D",SUMIF(Akun!A:A,A17,Akun!F:F)+SUMIF(Jurnal!K:K,A17,Jurnal!N:N)-SUMIF(Jurnal!K:K,A17,Jurnal!O:O),0) -> 0 | E17: =IF(C17="K",SUMIF(Akun!A:A,A17,Akun!G:G)-SUMIF(Jurnal!K:K,A17,Jurnal!N:N)+SUMIF(Jurnal!K:K,A17,Jurnal!O:O),0) -> 0 | F17: =VLOOKUP(A17,DAF_AKUN,4,FALSE) -> NR | G17: =IF(F17="LR",D17,0) -> 0 | H17: =IF(F17="LR",E17,0) -> 0 | I17: =IF(F17="NR",D17,0) -> 0 | J17: =IF(F17="NR",E17,0) -> 0
A18: 11301 | B18: =VLOOKUP(A18,DAF_AKUN,2,FALSE) -> Persediaan Bahan Baku | C18: =VLOOKUP(A18,DAF_AKUN,3,FALSE) -> D | D18: =IF(C18="D",SUMIF(Akun!A:A,A18,Akun!F:F)+SUMIF(Jurnal!K:K,A18,Jurnal!N:N)-SUMIF(Jurnal!K:K,A18,Jurnal!O:O),0) -> 10187858027 | E18: =IF(C18="K",SUMIF(Akun!A:A,A18,Akun!G:G)-SUMIF(Jurnal!K:K,A18,Jurnal!N:N)+SUMIF(Jurnal!K:K,A18,Jurnal!O:O),0) -> 0 | F18: =VLOOKUP(A18,DAF_AKUN,4,FALSE) -> NR | G18: =IF(F18="LR",D18,0) -> 0 | H18: =IF(F18="LR",E18,0) -> 0 | I18: =IF(F18="NR",D18,0) -> 10187858027 | J18: =IF(F18="NR",E18,0) -> 0
A19: 11400 | B19: =VLOOKUP(A19,DAF_AKUN,2,FALSE) -> Persediaan Bahan Penolong | C19: =VLOOKUP(A19,DAF_AKUN,3,FALSE) -> D | D19: =IF(C19="D",SUMIF(Akun!A:A,A19,Akun!F:F)+SUMIF(Jurnal!K:K,A19,Jurnal!N:N)-SUMIF(Jurnal!K:K,A19,Jurnal!O:O),0) -> 0 | E19: =IF(C19="K",SUMIF(Akun!A:A,A19,Akun!G:G)-SUMIF(Jurnal!K:K,A19,Jurnal!N:N)+SUMIF(Jurnal!K:K,A19,Jurnal!O:O),0) -> 0 | F19: =VLOOKUP(A19,DAF_AKUN,4,FALSE) -> NR | G19: =IF(F19="LR",D19,0) -> 0 | H19: =IF(F19="LR",E19,0) -> 0 | I19: =IF(F19="NR",D19,0) -> 0 | J19: =IF(F19="NR",E19,0) -> 0
A20: 11401 | B20: =VLOOKUP(A20,DAF_AKUN,2,FALSE) -> Persediaan Lain-lain | C20: =VLOOKUP(A20,DAF_AKUN,3,FALSE) -> D | D20: =IF(C20="D",SUMIF(Akun!A:A,A20,Akun!F:F)+SUMIF(Jurnal!K:K,A20,Jurnal!N:N)-SUMIF(Jurnal!K:K,A20,Jurnal!O:O),0) -> 5860000 | E20: =IF(C20="K",SUMIF(Akun!A:A,A20,Akun!G:G)-SUMIF(Jurnal!K:K,A20,Jurnal!N:N)+SUMIF(Jurnal!K:K,A20,Jurnal!O:O),0) -> 0 | F20: =VLOOKUP(A20,DAF_AKUN,4,FALSE) -> NR | G20: =IF(F20="LR",D20,0) -> 0 | H20: =IF(F20="LR",E20,0) -> 0 | I20: =IF(F20="NR",D20,0) -> 5860000 | J20: =IF(F20="NR",E20,0) -> 0
A21: 11402 | B21: =VLOOKUP(A21,DAF_AKUN,2,FALSE) -> Ppn Dibayar dimuka | C21: =VLOOKUP(A21,DAF_AKUN,3,FALSE) -> D | D21: =IF(C21="D",SUMIF(Akun!A:A,A21,Akun!F:F)+SUMIF(Jurnal!K:K,A21,Jurnal!N:N)-SUMIF(Jurnal!K:K,A21,Jurnal!O:O),0) -> 0 | E21: =IF(C21="K",SUMIF(Akun!A:A,A21,Akun!G:G)-SUMIF(Jurnal!K:K,A21,Jurnal!N:N)+SUMIF(Jurnal!K:K,A21,Jurnal!O:O),0) -> 0 | F21: =VLOOKUP(A21,DAF_AKUN,4,FALSE) -> NR | G21: =IF(F21="LR",D21,0) -> 0 | H21: =IF(F21="LR",E21,0) -> 0 | I21: =IF(F21="NR",D21,0) -> 0 | J21: =IF(F21="NR",E21,0) -> 0
A22: 11403 | B22: =VLOOKUP(A22,DAF_AKUN,2,FALSE) -> Pph Pasal 23 | C22: =VLOOKUP(A22,DAF_AKUN,3,FALSE) -> D | D22: =IF(C22="D",SUMIF(Akun!A:A,A22,Akun!F:F)+SUMIF(Jurnal!K:K,A22,Jurnal!N:N)-SUMIF(Jurnal!K:K,A22,Jurnal!O:O),0) -> 14360087 | E22: =IF(C22="K",SUMIF(Akun!A:A,A22,Akun!G:G)-SUMIF(Jurnal!K:K,A22,Jurnal!N:N)+SUMIF(Jurnal!K:K,A22,Jurnal!O:O),0) -> 0 | F22: =VLOOKUP(A22,DAF_AKUN,4,FALSE) -> NR | G22: =IF(F22="LR",D22,0) -> 0 | H22: =IF(F22="LR",E22,0) -> 0 | I22: =IF(F22="NR",D22,0) -> 14360087 | J22: =IF(F22="NR",E22,0) -> 0
A23: 11500 | B23: =VLOOKUP(A23,DAF_AKUN,2,FALSE) -> Pph Pasal 25 | C23: =VLOOKUP(A23,DAF_AKUN,3,FALSE) -> D | D23: =IF(C23="D",SUMIF(Akun!A:A,A23,Akun!F:F)+SUMIF(Jurnal!K:K,A23,Jurnal!N:N)-SUMIF(Jurnal!K:K,A23,Jurnal!O:O),0) -> 12140000 | E23: =IF(C23="K",SUMIF(Akun!A:A,A23,Akun!G:G)-SUMIF(Jurnal!K:K,A23,Jurnal!N:N)+SUMIF(Jurnal!K:K,A23,Jurnal!O:O),0) -> 0 | F23: =VLOOKUP(A23,DAF_AKUN,4,FALSE) -> NR | G23: =IF(F23="LR",D23,0) -> 0 | H23: =IF(F23="LR",E23,0) -> 0 | I23: =IF(F23="NR",D23,0) -> 12140000 | J23: =IF(F23="NR",E23,0) -> 0
... A26: 11800 | B26: =VLOOKUP(A26,DAF_AKUN,2,FALSE) -> Uang Muka Sewa | C26: =VLOOKUP(A26,DAF_AKUN,3,FALSE) -> D | D26: =IF(C26="D",SUMIF(Akun!A:A,A26,Akun!F:F)+SUMIF(Jurnal!K:K,A26,Jurnal!N:N)-SUMIF(Jurnal!K:K,A26,Jurnal!O:O),0) -> 0 | E26: =IF(C26="K",SUMIF(Akun!A:A,A26,Akun!G:G)-SUMIF(Jurnal!K:K,A26,Jurnal!N:N)+SUMIF(Jurnal!K:K,A26,Jurnal!O:O),0) -> 0 | F26: =VLOOKUP(A26,DAF_AKUN,4,FALSE) -> NR | G26: =IF(F26="LR",D26,0) -> 0 | H26: =IF(F26="LR",E26,0) -> 0 | I26: =IF(F26="NR",D26,0) -> 0 | J26: =IF(F26="NR",E26,0) -> 0
A27: 12000 | B27: =VLOOKUP(A27,DAF_AKUN,2,FALSE) -> AKTIVA TETAP
A28: 12100 | B28: =VLOOKUP(A28,DAF_AKUN,2,FALSE) -> Gedung dan Listrik | C28: =VLOOKUP(A28,DAF_AKUN,3,FALSE) -> D | D28: =IF(C28="D",SUMIF(Akun!A:A,A28,Akun!F:F)+SUMIF(Jurnal!K:K,A28,Jurnal!N:N)-SUMIF(Jurnal!K:K,A28,Jurnal!O:O),0) -> 48589042 | E28: =IF(C28="K",SUMIF(Akun!A:A,A28,Akun!G:G)-SUMIF(Jurnal!K:K,A28,Jurnal!N:N)+SUMIF(Jurnal!K:K,A28,Jurnal!O:O),0) -> 0 | F28: =IF(ERR=FALSE,0,VLOOKUP(A28,DAF_AKUN,4,FALSE)) -> NR | G28: =IF(F28="LR",D28,0) -> 0 | H28: =IF(F28="LR",E28,0) -> 0 | I28: =IF(F28="NR",D28,0) -> 48589042 | J28: =IF(F28="NR",E28,0) -> 0
A29: 12200 | B29: =VLOOKUP(A29,DAF_AKUN,2,FALSE) -> Peralatan Pabrik | C29: =VLOOKUP(A29,DAF_AKUN,3,FALSE) -> D | D29: =IF(C29="D",SUMIF(Akun!A:A,A29,Akun!F:F)+SUMIF(Jurnal!K:K,A29,Jurnal!N:N)-SUMIF(Jurnal!K:K,A29,Jurnal!O:O),0) -> 6747617604 | E29: =IF(C29="K",SUMIF(Akun!A:A,A29,Akun!G:G)-SUMIF(Jurnal!K:K,A29,Jurnal!N:N)+SUMIF(Jurnal!K:K,A29,Jurnal!O:O),0) -> 0 | F29: =IF(ERR=FALSE,0,VLOOKUP(A29,DAF_AKUN,4,FALSE)) -> NR | G29: =IF(F29="LR",D29,0) -> 0 | H29: =IF(F29="LR",E29,0) -> 0 | I29: =IF(F29="NR",D29,0) -> 6747617604 | J29: =IF(F29="NR",E29,0) -> 0
A30: 12300 | B30: =VLOOKUP(A30,DAF_AKUN,2,FALSE) -> Peralatan Kantor | C30: =VLOOKUP(A30,DAF_AKUN,3,FALSE) -> D | D30: =IF(C30="D",SUMIF(Akun!A:A,A30,Akun!F:F)+SUMIF(Jurnal!K:K,A30,Jurnal!N:N)-SUMIF(Jurnal!K:K,A30,Jurnal!O:O),0) -> 214765469 | E30: =IF(C30="K",SUMIF(Akun!A:A,A30,Akun!G:G)-SUMIF(Jurnal!K:K,A30,Jurnal!N:N)+SUMIF(Jurnal!K:K,A30,Jurnal!O:O),0) -> 0 | F30: =IF(ERR=FALSE,0,VLOOKUP(A30,DAF_AKUN,4,FALSE)) -> NR | G30: =IF(F30="LR",D30,0) -> 0 | H30: =IF(F30="LR",E30,0) -> 0 | I30: =IF(F30="NR",D30,0) -> 214765469 | J30: =IF(F30="NR",E30,0) -> 0
A31: 12400 | B31: =VLOOKUP(A31,DAF_AKUN,2,FALSE) -> Kendaraan | C31: =VLOOKUP(A31,DAF_AKUN,3,FALSE) -> D | D31: =IF(C31="D",SUMIF(Akun!A:A,A31,Akun!F:F)+SUMIF(Jurnal!K:K,A31,Jurnal!N:N)-SUMIF(Jurnal!K:K,A31,Jurnal!O:O),0) -> 0 | E31: =IF(C31="K",SUMIF(Akun!A:A,A31,Akun!G:G)-SUMIF(Jurnal!K:K,A31,Jurnal!N:N)+SUMIF(Jurnal!K:K,A31,Jurnal!O:O),0) -> 0 | F31: =IF(ERR=FALSE,0,VLOOKUP(A31,DAF_AKUN,4,FALSE)) -> NR | G31: =IF(F31="LR",D31,0) -> 0 | H31: =IF(F31="LR",E31,0) -> 0 | I31: =IF(F31="NR",D31,0) -> 0 | J31: =IF(F31="NR",E31,0) -> 0
